Workbook

Sheet Prices
A1: Date | B1: S&P 500 | C1: AAPL.US | D1: MSFT.US | E1: GOOGL.US | F1: NVDA.US | G1: META.US | H1: JNJ.US | I1: PFE.US | J1: UNH.US | K1: MRK.US | L1: ABBV.US | M1: XOM.US | N1: CVX.US | O1: COP.US | P1: SLB.US | Q1: OXY.US | R1: AMZN.US | S1: TSLA.US | T1: NKE.US | U1: HD.US | V1: MCD.US
A2: 11/30/2019 | B2: 3140.98 | C2: 64.7028 | D2: 144.81 | E2: 64.9689 | F2: 5.39616 | G2: 201.64 | H2: 127.221 | I2: 34.4945 | J2: 256.13 | K2: 74.2955 | L2: 76.3487 | M2: 57.1669 | N2: 101.663 | O2: 53.7057 | P2: 33.4143 | Q2: 36.247 | R2: 90.04 | S2: 21.996 | T2: 90.9452 | U2: 204.532 | V2: 181.422
A3: 12/31/2019 | B3: 3230.78 | C3: 71.0911 | D3: 150.829 | E3: 66.7276 | F3: 5.85806 | G3: 205.25 | H3: 134.967 | I3: 35.0859 | J3: 270.074 | K3: 78.0395 | L3: 77.0538 | M3: 58.5536 | N3: 104.598 | O3: 58.2669 | P3: 37.6249 | Q3: 39.5284 | R3: 92.392 | S3: 27.8887 | T3: 98.5707 | U3: 203.855 | V3: 184.364
A4: 1/31/2020 | B4: 3225.52 | C4: 74.9374 | D4: 162.823 | E4: 71.3803 | F4: 5.8861 | G4: 201.91 | H4: 137.743 | I4: 33.6894 | J4: 250.299 | K4: 73.3116 | L4: 71.4607 | M4: 52.1264 | N4: 93.003 | O4: 53.2486 | P4: 31.3623 | Q4: 38.1009 | R4: 100.436 | S4: 43.37 | T4: 93.6761 | U4: 212.922 | V4: 199.608
A5: 2/29/2020 | B5: 2954.22 | C5: 66.3379 | D5: 155.378 | E5: 66.7206 | F5: 6.72787 | G5: 192.47 | H5: 125.22 | I5: 30.2327 | J5: 234.219 | K5: 65.6928 | L5: 75.5994 | M5: 43.7842 | N5: 81.9648 | O5: 43.6911 | P5: 25.7284 | Q5: 31.4039 | R5: 94.1875 | S5: 44.5333 | T5: 87.1829 | U5: 203.355 | V5: 182.279
A6: 3/31/2020 | B6: 2584.59 | C6: 61.709 | D6: 151.258 | E6: 57.8877 | F6: 6.5664 | G6: 166.8 | H6: 122.111 | I6: 29.5261 | J6: 230.081 | K6: 66.564 | L6: 67.2022 | M6: 32.3174 | N6: 63.6289 | O6: 27.7921 | P6: 12.8127 | Q6: 11.4438 | R6: 97.486 | S6: 34.9333 | T6: 80.7057 | U6: 175.464 | V6: 155.222
A7: 4/30/2020 | B7: 2912.43 | C7: 71.299 | D7: 171.878 | E7: 67.0918 | F7: 7.28084 | G7: 204.71 | H7: 139.713 | I7: 34.7024 | J7: 269.853 | K7: 68.6399 | L7: 73.584 | M7: 39.5528 | N7: 80.7876 | O7: 37.9884 | P7: 15.9747 | Q7: 16.4043 | R7: 123.7 | S7: 52.1267 | T7: 85.0371 | U7: 206.573 | V7: 176.072
A8: 5/31/2020 | B8: 3044.31 | C8: 77.3669 | D8: 176.242 | E8: 71.4171 | F8: 8.84379 | G8: 225.09 | H8: 139.479 | I8: 34.8926 | J8: 281.248 | K8: 69.8339 | L8: 82.957 | M8: 39.4527 | N8: 81.7064 | O8: 38.4408 | P8: 17.5423 | Q8: 12.7987 | R8: 122.118 | S8: 55.6667 | T8: 96.3971 | U8: 233.501 | V8: 176.072
A9: 6/30/2020 | B9: 3100.29 | C9: 88.7671 | D9: 195.719 | E9: 70.6463 | F9: 9.46818 | G9: 227.07 | H9: 131.868 | I9: 29.8755 | J9: 273.312 | K9: 67.4338 | L9: 87.8892 | M9: 38.802 | N9: 79.5049 | O9: 38.2967 | P9: 17.5848 | Q9: 18.0961 | R9: 137.941 | S9: 71.9867 | T9: 95.8785 | U9: 236.827 | V9: 174.331
A10: 7/31/2020 | B10: 3271.12 | C10: 103.436 | D10: 197.173 | E10: 74.1287 | F10: 10.5813 | G10: 253.67 | H10: 136.674 | I10: 35.4997 | J10: 280.575 | K10: 69.9709 | L10: 85.9993 | M10: 36.5118 | N10: 74.791 | O10: 34.4234 | P10: 17.3466 | Q10: 15.5663 | R10: 158.234 | S10: 95.3833 | T10: 95.4481 | U10: 250.989 | V10: 183.606
A11: 8/31/2020 | B11: 3500.31 | C11: 125.829 | D11: 217.421 | E11: 81.1823 | F11: 13.3331 | G11: 293.2 | H11: 144.803 | I11: 34.8634 | J11: 289.608 | K11: 74.3555 | L11: 86.778 | M11: 35.337 | N11: 75.861 | O11: 34.8845 | P11: 18.1779 | Q11: 12.5988 | R11: 172.548 | S11: 166.107 | T11: 109.664 | U11: 269.448 | V11: 202.963
A12: 9/30/2020 | B12: 3363 | C12: 112.918 | D12: 202.781 | E12: 73.0153 | F12: 13.4928 | G12: 261.9 | H12: 140.528 | I12: 33.8582 | J12: 290.084 | K12: 72.8608 | L12: 79.3655 | M12: 30.3753 | N12: 65.0773 | O12: 30.2352 | P12: 14.9784 | Q12: 9.90895 | R12: 157.436 | S12: 143.003 | T12: 123.04 | U12: 263.913 | V12: 208.638
A13: 10/31/2020 | B13: 3269.96 | C13: 106.149 | D13: 195.211 | E13: 80.5136 | F13: 12.4984 | G13: 263.11 | H13: 129.417 | I13: 32.733 | J13: 283.91 | K13: 66.0623 | L13: 78.1612 | M13: 28.8621 | N13: 62.8174 | O13: 26.6731 | P13: 14.3814 | Q13: 9.03674 | R13: 151.808 | S13: 129.347 | T13: 117.687 | U13: 253.452 | V13: 202.461
... A62: 11/30/2024 | B62: 6032.38 | C62: 237.069 | D62: 423.46 | E62: 168.757 | F62: 138.24 | G62: 574.32 | H62: 155.01 | I62: 26.21 | J62: 601.016 | K62: 100.833 | L62: 182.93 | M62: 117.96 | N62: 161.93 | O62: 108.34 | P62: 43.94 | Q62: 50.58 | R62: 207.89 | S62: 345.16 | T62: 78.77 | U62: 429.13 | V62: 296.01

Sheet Returns
A1: Date | B1: S&P 500 | C1: AAPL.US | D1: MSFT.US | E1: GOOGL.US | F1: NVDA.US | G1: META.US | H1: JNJ.US | I1: PFE.US | J1: UNH.US | K1: MRK.US | L1: ABBV.US | M1: XOM.US | N1: CVX.US | O1: COP.US | P1: SLB.US | Q1: OXY.US | R1: AMZN.US | S1: TSLA.US | T1: NKE.US | U1: HD.US | V1: MCD.US
A2: 11/30/2019 | B2: N/A | C2: N/A | D2: N/A | E2: N/A | F2: N/A | G2: N/A | H2: N/A | I2: N/A | J2: N/A | K2: N/A | L2: N/A | M2: N/A | N2: N/A | O2: N/A | P2: N/A | Q2: N/A | R2: N/A | S2: N/A | T2: N/A | U2: N/A | V2: N/A
A3: 12/31/2019 | B3: =(Prices!B3 / Prices!B2) - 1 -> 0.028589803 | C3: =(Prices!C3 / Prices!C2) - 1 -> 0.098732976 | D3: =(Prices!D3 / Prices!D2) - 1 -> 0.041564809 | E3: =(Prices!E3 / Prices!E2) - 1 -> 0.027069875 | F3: =(Prices!F3 / Prices!F2) - 1 -> 0.085597907 | G3: =(Prices!G3 / Prices!G2) - 1 -> 0.017903194 | H3: =(Prices!H3 / Prices!H2) - 1 -> 0.060886174 | I3: =(Prices!I3 / Prices!I2) - 1 -> 0.017144762 | ... V3: =(Prices!V3 / Prices!V2) - 1 -> 0.016216335
A4: 1/31/2020 | B4: =(Prices!B4 / Prices!B3) - 1 -> -0.0016280898 | C4: =(Prices!C4 / Prices!C3) - 1 -> 0.054103819 | D4: =(Prices!D4 / Prices!D3) - 1 -> 0.079520517 | E4: =(Prices!E4 / Prices!E3) - 1 -> 0.06972677 | F4: =(Prices!F4 / Prices!F3) - 1 -> 0.0047865676 | G4: =(Prices!G4 / Prices!G3) - 1 -> -0.016272838 | H4: =(Prices!H4 / Prices!H3) - 1 -> 0.020567991 | I4: =(Prices!I4 / Prices!I3) - 1 -> -0.039802314 | ... V4: =(Prices!V4 / Prices!V3) - 1 -> 0.082684255
A5: 2/29/2020 | B5: =(Prices!B5 / Prices!B4) - 1 -> -0.084110469 | C5: =(Prices!C5 / Prices!C4) - 1 -> -0.11475578 | D5: =(Prices!D5 / Prices!D4) - 1 -> -0.045724498 | E5: =(Prices!E5 / Prices!E4) - 1 -> -0.065279916 | F5: =(Prices!F5 / Prices!F4) - 1 -> 0.1430098 | G5: =(Prices!G5 / Prices!G4) - 1 -> -0.046753504 | H5: =(Prices!H5 / Prices!H4) - 1 -> -0.090915691 | I5: =(Prices!I5 / Prices!I4) - 1 -> -0.10260497 | ... V5: =(Prices!V5 / Prices!V4) - 1 -> -0.086815158
A6: 3/31/2020 | B6: =(Prices!B6 / Prices!B5) - 1 -> -0.12511932 | C6: =(Prices!C6 / Prices!C5) - 1 -> -0.069777608 | D6: =(Prices!D6 / Prices!D5) - 1 -> -0.02651598 | E6: =(Prices!E6 / Prices!E5) - 1 -> -0.1323864 | F6: =(Prices!F6 / Prices!F5) - 1 -> -0.024000166 | G6: =(Prices!G6 / Prices!G5) - 1 -> -0.13337143 | H6: =(Prices!H6 / Prices!H5) - 1 -> -0.024828302 | I6: =(Prices!I6 / Prices!I5) - 1 -> -0.023372044 | ... V6: =(Prices!V6 / Prices!V5) - 1 -> -0.14843729
A7: 4/30/2020 | B7: =(Prices!B7 / Prices!B6) - 1 -> 0.1268441 | C7: =(Prices!C7 / Prices!C6) - 1 -> 0.15540683 | D7: =(Prices!D7 / Prices!D6) - 1 -> 0.13632337 | E7: =(Prices!E7 / Prices!E6) - 1 -> 0.15899923 | F7: =(Prices!F7 / Prices!F6) - 1 -> 0.10880239 | G7: =(Prices!G7 / Prices!G6) - 1 -> 0.22727818 | H7: =(Prices!H7 / Prices!H6) - 1 -> 0.14414754 | I7: =(Prices!I7 / Prices!I6) - 1 -> 0.17531269 | ... V7: =(Prices!V7 / Prices!V6) - 1 -> 0.13432374
A8: 5/31/2020 | B8: =(Prices!B8 / Prices!B7) - 1 -> 0.045281775 | C8: =(Prices!C8 / Prices!C7) - 1 -> 0.08510498 | D8: =(Prices!D8 / Prices!D7) - 1 -> 0.025390102 | E8: =(Prices!E8 / Prices!E7) - 1 -> 0.064468385 | F8: =(Prices!F8 / Prices!F7) - 1 -> 0.21466616 | G8: =(Prices!G8 / Prices!G7) - 1 -> 0.099555469 | H8: =(Prices!H8 / Prices!H7) - 1 -> -0.001674862 | I8: =(Prices!I8 / Prices!I7) - 1 -> 0.0054808889 | ... V8: =(Prices!V8 / Prices!V7) - 1 -> 0
A9: 6/30/2020 | B9: =(Prices!B9 / Prices!B8) - 1 -> 0.018388403 | C9: =(Prices!C9 / Prices!C8) - 1 -> 0.14735242 | D9: =(Prices!D9 / Prices!D8) - 1 -> 0.11051282 | E9: =(Prices!E9 / Prices!E8) - 1 -> -0.010792933 | F9: =(Prices!F9 / Prices!F8) - 1 -> 0.070602083 | G9: =(Prices!G9 / Prices!G8) - 1 -> 0.0087964814 | H9: =(Prices!H9 / Prices!H8) - 1 -> -0.054567354 | I9: =(Prices!I9 / Prices!I8) - 1 -> -0.14378693 | ... V9: =(Prices!V9 / Prices!V8) - 1 -> -0.0098880004
A10: 7/31/2020 | B10: =(Prices!B10 / Prices!B9) - 1 -> 0.055101297 | C10: =(Prices!C10 / Prices!C9) - 1 -> 0.16525154 | D10: =(Prices!D10 / Prices!D9) - 1 -> 0.0074290181 | E10: =(Prices!E10 / Prices!E9) - 1 -> 0.049293452 | F10: =(Prices!F10 / Prices!F9) - 1 -> 0.1175643 | G10: =(Prices!G10 / Prices!G9) - 1 -> 0.11714449 | H10: =(Prices!H10 / Prices!H9) - 1 -> 0.036445536 | I10: =(Prices!I10 / Prices!I9) - 1 -> 0.18825459 | ... V10: =(Prices!V10 / Prices!V9) - 1 -> 0.053203389
A11: 8/31/2020 | B11: =(Prices!B11 / Prices!B10) - 1 -> 0.070064687 | C11: =(Prices!C11 / Prices!C10) - 1 -> 0.21649136 | D11: =(Prices!D11 / Prices!D10) - 1 -> 0.10269154 | E11: =(Prices!E11 / Prices!E10) - 1 -> 0.095153429 | F11: =(Prices!F11 / Prices!F10) - 1 -> 0.26006256 | G11: =(Prices!G11 / Prices!G10) - 1 -> 0.15583238 | H11: =(Prices!H11 / Prices!H10) - 1 -> 0.059477296 | I11: =(Prices!I11 / Prices!I10) - 1 -> -0.017924095 | ... V11: =(Prices!V11 / Prices!V10) - 1 -> 0.10542684
A12: 9/30/2020 | B12: =(Prices!B12 / Prices!B11) - 1 -> -0.039227954 | C12: =(Prices!C12 / Prices!C11) - 1 -> -0.10260751 | D12: =(Prices!D12 / Prices!D11) - 1 -> -0.067334802 | E12: =(Prices!E12 / Prices!E11) - 1 -> -0.10060075 | F12: =(Prices!F12 / Prices!F11) - 1 -> 0.01197771 | G12: =(Prices!G12 / Prices!G11) - 1 -> -0.10675307 | H12: =(Prices!H12 / Prices!H11) - 1 -> -0.029522869 | I12: =(Prices!I12 / Prices!I11) - 1 -> -0.028832529 | ... V12: =(Prices!V12 / Prices!V11) - 1 -> 0.027960761
A13: 10/31/2020 | B13: =(Prices!B13 / Prices!B12) - 1 -> -0.027665775 | C13: =(Prices!C13 / Prices!C12) - 1 -> -0.059946156 | D13: =(Prices!D13 / Prices!D12) - 1 -> -0.037330914 | E13: =(Prices!E13 / Prices!E12) - 1 -> 0.10269491 | F13: =(Prices!F13 / Prices!F12) - 1 -> -0.073698565 | G13: =(Prices!G13 / Prices!G12) - 1 -> 0.004620084 | H13: =(Prices!H13 / Prices!H12) - 1 -> -0.079066094 | I13: =(Prices!I13 / Prices!I12) - 1 -> -0.033232718 | ... V13: =(Prices!V13 / Prices!V12) - 1 -> -0.029606304
A14: 11/30/2020 | B14: =(Prices!B14 / Prices!B13) - 1 -> 0.10754566 | C14: =(Prices!C14 / Prices!C13) - 1 -> 0.095535521 | D14: =(Prices!D14 / Prices!D13) - 1 -> 0.059986374 | E14: =(Prices!E14 / Prices!E13) - 1 -> 0.085569394 | F14: =(Prices!F14 / Prices!F13) - 1 -> 0.069264866 | G14: =(Prices!G14 / Prices!G13) - 1 -> 0.052677587 | H14: =(Prices!H14 / Prices!H13) - 1 -> 0.062588377 | I14: =(Prices!I14 / Prices!I13) - 1 -> 0.090874652 | ... V14: =(Prices!V14 / Prices!V13) - 1 -> 0.026913825
... A62: 11/30/2024 | B62: =(Prices!B62 / Prices!B61) - 1 -> 0.057301352 | C62: =(Prices!C62 / Prices!C61) - 1 -> 0.051704863 | D62: =(Prices!D62 / Prices!D61) - 1 -> 0.044193146 | E62: =(Prices!E62 / Prices!E61) - 1 -> -0.012620382 | F62: =(Prices!F62 / Prices!F61) - 1 -> 0.041348088 | G62: =(Prices!G62 / Prices!G61) - 1 -> 0.011874978 | H62: =(Prices!H62 / Prices!H61) - 1 -> -0.030339047 | I62: =(Prices!I62 / Prices!I61) - 1 -> -0.07385159 | ... V62: =(Prices!V62 / Prices!V61) - 1 -> 0.013351135

Sheet Excess_Returns
A1: Date | B1: S&P 500 | C1: AAPL.US | D1: MSFT.US | E1: GOOGL.US | F1: NVDA.US | G1: META.US | H1: JNJ.US | I1: PFE.US | J1: UNH.US | K1: MRK.US | L1: ABBV.US | M1: XOM.US | N1: CVX.US | O1: COP.US | P1: SLB.US | Q1: OXY.US | R1: AMZN.US | S1: TSLA.US | T1: NKE.US | U1: HD.US | V1: MCD.US
A2: 11/30/2019
A3: 12/31/2019 | B3: =Returns!B3 - RiskFree!$C3 -> 0.02730647 | C3: =Returns!C3 - RiskFree!$C3 -> 0.097449643 | D3: =Returns!D3 - RiskFree!$C3 -> 0.040281476 | E3: =Returns!E3 - RiskFree!$C3 -> 0.025786542 | F3: =Returns!F3 - RiskFree!$C3 -> 0.084314573 | G3: =Returns!G3 - RiskFree!$C3 -> 0.01661986 | H3: =Returns!H3 - RiskFree!$C3 -> 0.059602841 | I3: =Returns!I3 - RiskFree!$C3 -> 0.015861429 | ... V3: =Returns!V3 - RiskFree!$C3 -> 0.014933002
A4: 1/31/2020 | B4: =Returns!B4 - RiskFree!$C4 -> -0.0028947565 | C4: =Returns!C4 - RiskFree!$C4 -> 0.052837152 | D4: =Returns!D4 - RiskFree!$C4 -> 0.07825385 | E4: =Returns!E4 - RiskFree!$C4 -> 0.068460103 | F4: =Returns!F4 - RiskFree!$C4 -> 0.0035199009 | G4: =Returns!G4 - RiskFree!$C4 -> -0.017539505 | H4: =Returns!H4 - RiskFree!$C4 -> 0.019301324 | I4: =Returns!I4 - RiskFree!$C4 -> -0.04106898 | ... V4: =Returns!V4 - RiskFree!$C4 -> 0.081417588
A5: 2/29/2020 | B5: =Returns!B5 - RiskFree!$C5 -> -0.085377136 | C5: =Returns!C5 - RiskFree!$C5 -> -0.11602245 | D5: =Returns!D5 - RiskFree!$C5 -> -0.046991165 | E5: =Returns!E5 - RiskFree!$C5 -> -0.066546583 | F5: =Returns!F5 - RiskFree!$C5 -> 0.14174314 | G5: =Returns!G5 - RiskFree!$C5 -> -0.048020171 | H5: =Returns!H5 - RiskFree!$C5 -> -0.092182357 | I5: =Returns!I5 - RiskFree!$C5 -> -0.10387164 | ... V5: =Returns!V5 - RiskFree!$C5 -> -0.088081824
A6: 3/31/2020 | B6: =Returns!B6 - RiskFree!$C6 -> -0.12536099 | C6: =Returns!C6 - RiskFree!$C6 -> -0.070019275 | D6: =Returns!D6 - RiskFree!$C6 -> -0.026757647 | E6: =Returns!E6 - RiskFree!$C6 -> -0.13262807 | F6: =Returns!F6 - RiskFree!$C6 -> -0.024241833 | G6: =Returns!G6 - RiskFree!$C6 -> -0.1336131 | H6: =Returns!H6 - RiskFree!$C6 -> -0.025069969 | I6: =Returns!I6 - RiskFree!$C6 -> -0.023613711 | ... V6: =Returns!V6 - RiskFree!$C6 -> -0.14867895
A7: 4/30/2020 | B7: =Returns!B7 - RiskFree!$C7 -> 0.12672744 | C7: =Returns!C7 - RiskFree!$C7 -> 0.15529016 | D7: =Returns!D7 - RiskFree!$C7 -> 0.1362067 | E7: =Returns!E7 - RiskFree!$C7 -> 0.15888257 | F7: =Returns!F7 - RiskFree!$C7 -> 0.10868572 | G7: =Returns!G7 - RiskFree!$C7 -> 0.22716151 | H7: =Returns!H7 - RiskFree!$C7 -> 0.14403087 | I7: =Returns!I7 - RiskFree!$C7 -> 0.17519602 | ... V7: =Returns!V7 - RiskFree!$C7 -> 0.13420708
A8: 5/31/2020 | B8: =Returns!B8 - RiskFree!$C8 -> 0.045173442 | C8: =Returns!C8 - RiskFree!$C8 -> 0.084996647 | D8: =Returns!D8 - RiskFree!$C8 -> 0.025281769 | E8: =Returns!E8 - RiskFree!$C8 -> 0.064360052 | F8: =Returns!F8 - RiskFree!$C8 -> 0.21455783 | G8: =Returns!G8 - RiskFree!$C8 -> 0.099447135 | H8: =Returns!H8 - RiskFree!$C8 -> -0.0017831954 | I8: =Returns!I8 - RiskFree!$C8 -> 0.0053725556 | ... V8: =Returns!V8 - RiskFree!$C8 -> -0.00010833333
A9: 6/30/2020 | B9: =Returns!B9 - RiskFree!$C9 -> 0.01825507 | C9: =Returns!C9 - RiskFree!$C9 -> 0.14721909 | D9: =Returns!D9 - RiskFree!$C9 -> 0.11037948 | E9: =Returns!E9 - RiskFree!$C9 -> -0.010926267 | F9: =Returns!F9 - RiskFree!$C9 -> 0.07046875 | G9: =Returns!G9 - RiskFree!$C9 -> 0.0086631481 | H9: =Returns!H9 - RiskFree!$C9 -> -0.054700688 | I9: =Returns!I9 - RiskFree!$C9 -> -0.14392027 | ... V9: =Returns!V9 - RiskFree!$C9 -> -0.010021334
A10: 7/31/2020 | B10: =Returns!B10 - RiskFree!$C10 -> 0.054992964 | C10: =Returns!C10 - RiskFree!$C10 -> 0.16514321 | D10: =Returns!D10 - RiskFree!$C10 -> 0.0073206848 | E10: =Returns!E10 - RiskFree!$C10 -> 0.049185119 | F10: =Returns!F10 - RiskFree!$C10 -> 0.11745597 | G10: =Returns!G10 - RiskFree!$C10 -> 0.11703616 | H10: =Returns!H10 - RiskFree!$C10 -> 0.036337203 | I10: =Returns!I10 - RiskFree!$C10 -> 0.18814626 | ... V10: =Returns!V10 - RiskFree!$C10 -> 0.053095056
A11: 8/31/2020 | B11: =Returns!B11 - RiskFree!$C11 -> 0.069981354 | C11: =Returns!C11 - RiskFree!$C11 -> 0.21640802 | D11: =Returns!D11 - RiskFree!$C11 -> 0.10260821 | E11: =Returns!E11 - RiskFree!$C11 -> 0.095070096 | F11: =Returns!F11 - RiskFree!$C11 -> 0.25997923 | G11: =Returns!G11 - RiskFree!$C11 -> 0.15574905 | H11: =Returns!H11 - RiskFree!$C11 -> 0.059393963 | I11: =Returns!I11 - RiskFree!$C11 -> -0.018007428 | ... V11: =Returns!V11 - RiskFree!$C11 -> 0.1053435
A12: 9/30/2020 | B12: =Returns!B12 - RiskFree!$C12 -> -0.039319621 | C12: =Returns!C12 - RiskFree!$C12 -> -0.10269917 | D12: =Returns!D12 - RiskFree!$C12 -> -0.067426469 | E12: =Returns!E12 - RiskFree!$C12 -> -0.10069241 | F12: =Returns!F12 - RiskFree!$C12 -> 0.011886043 | G12: =Returns!G12 - RiskFree!$C12 -> -0.10684474 | H12: =Returns!H12 - RiskFree!$C12 -> -0.029614536 | I12: =Returns!I12 - RiskFree!$C12 -> -0.028924196 | ... V12: =Returns!V12 - RiskFree!$C12 -> 0.027869095
A13: 10/31/2020 | B13: =Returns!B13 - RiskFree!$C13 -> -0.027749108 | C13: =Returns!C13 - RiskFree!$C13 -> -0.060029489 | D13: =Returns!D13 - RiskFree!$C13 -> -0.037414247 | E13: =Returns!E13 - RiskFree!$C13 -> 0.10261158 | F13: =Returns!F13 - RiskFree!$C13 -> -0.073781898 | G13: =Returns!G13 - RiskFree!$C13 -> 0.0045367507 | H13: =Returns!H13 - RiskFree!$C13 -> -0.079149427 | I13: =Returns!I13 - RiskFree!$C13 -> -0.033316051 | ... V13: =Returns!V13 - RiskFree!$C13 -> -0.029689637
A14: 11/30/2020 | B14: =Returns!B14 - RiskFree!$C14 -> 0.10747066 | C14: =Returns!C14 - RiskFree!$C14 -> 0.095460521 | D14: =Returns!D14 - RiskFree!$C14 -> 0.059911374 | E14: =Returns!E14 - RiskFree!$C14 -> 0.085494394 | F14: =Returns!F14 - RiskFree!$C14 -> 0.069189866 | G14: =Returns!G14 - RiskFree!$C14 -> 0.052602587 | H14: =Returns!H14 - RiskFree!$C14 -> 0.062513377 | I14: =Returns!I14 - RiskFree!$C14 -> 0.090799652 | ... V14: =Returns!V14 - RiskFree!$C14 -> 0.026838825
... A62: 11/30/2024 | B62: =Returns!B62 - RiskFree!$C62 -> 0.053618019 | C62: =Returns!C62 - RiskFree!$C62 -> 0.04802153 | D62: =Returns!D62 - RiskFree!$C62 -> 0.040509813 | E62: =Returns!E62 - RiskFree!$C62 -> -0.016303716 | F62: =Returns!F62 - RiskFree!$C62 -> 0.037664754 | G62: =Returns!G62 - RiskFree!$C62 -> 0.0081916446 | H62: =Returns!H62 - RiskFree!$C62 -> -0.03402238 | I62: =Returns!I62 - RiskFree!$C62 -> -0.077534923 | ... V62: =Returns!V62 - RiskFree!$C62 -> 0.0096678015

Sheet RiskFree
A1: observation_date | B1: TB3MS | C1: RF_Monthly | D1: MonthEnd
A2: 43770 | B2: 1.54 | C2: =(B2/100)/12 -> 0.0012833333 | D2: =EOMONTH(A2,0) -> 43799
A3: 43800 | B3: 1.54 | C3: =(B3/100)/12 -> 0.0012833333 | D3: =EOMONTH(A3,0) -> 43830
A4: 43831 | B4: 1.52 | C4: =(B4/100)/12 -> 0.0012666667 | D4: =EOMONTH(A4,0) -> 43861
A5: 43862 | B5: 1.52 | C5: =(B5/100)/12 -> 0.0012666667 | D5: =EOMONTH(A5,0) -> 43890
A6: 43891 | B6: 0.29 | C6: =(B6/100)/12 -> 0.00024166667 | D6: =EOMONTH(A6,0) -> 43921
A7: 43922 | B7: 0.14 | C7: =(B7/100)/12 -> 0.00011666667 | D7: =EOMONTH(A7,0) -> 43951
A8: 43952 | B8: 0.13 | C8: =(B8/100)/12 -> 0.00010833333 | D8: =EOMONTH(A8,0) -> 43982
A9: 43983 | B9: 0.16 | C9: =(B9/100)/12 -> 0.00013333333 | D9: =EOMONTH(A9,0) -> 44012
A10: 44013 | B10: 0.13 | C10: =(B10/100)/12 -> 0.00010833333 | D10: =EOMONTH(A10,0) -> 44043
A11: 44044 | B11: 0.1 | C11: =(B11/100)/12 -> 8.3333333e-05 | D11: =EOMONTH(A11,0) -> 44074
A12: 44075 | B12: 0.11 | C12: =(B12/100)/12 -> 9.1666667e-05 | D12: =EOMONTH(A12,0) -> 44104
A13: 44105 | B13: 0.1 | C13: =(B13/100)/12 -> 8.3333333e-05 | D13: =EOMONTH(A13,0) -> 44135
... A74: 45962 | B74: 3.78 | C74: =(B74/100)/12 -> 0.00315 | D74: =EOMONTH(A74,0) -> 45991

Sheet Stats
A1: Asset | B1: Mean_Excess_Return | C1: Std_Dev | E1: Beta
A2: S&P 500 | B2: =AVERAGE(Excess_Returns!B$2:B$62) -> 0.010249799 | C2: =_xlfn.STDEV.S(Excess_Returns!B2:B62) -> 0.052265948 | H2: Covariance Matrix (20 stocks) | I2: {=INDEX($A$3:$A$22, COLUMNS($I$2:I2))} -> AAPL.US | J2: {=INDEX($A$3:$A$22, COLUMNS($I$2:J2))} -> MSFT.US | K2: {=INDEX($A$3:$A$22, COLUMNS($I$2:K2))} -> GOOGL.US | L2: {=INDEX($A$3:$A$22, COLUMNS($I$2:L2))} -> NVDA.US | M2: {=INDEX($A$3:$A$22, COLUMNS($I$2:M2))} -> META.US | N2: {=INDEX($A$3:$A$22, COLUMNS($I$2:N2))} -> JNJ.US | O2: {=INDEX($A$3:$A$22, COLUMNS($I$2:O2))} -> PFE.US | P2: {=INDEX($A$3:$A$22, COLUMNS($I$2:P2))} -> UNH.US | ... AB2: {=INDEX($A$3:$A$22, COLUMNS($I$2:AB2))} -> MCD.US
A3: AAPL.US | B3: =AVERAGE(Excess_Returns!C$2:C$62) -> 0.023225347 | C3: =_xlfn.STDEV.S(Excess_Returns!C2:C62) -> 0.084189724 | E3: =SLOPE(Excess_Returns!$C$3:$C$62,Excess_Returns!$B$3:$B$62) -> 1.2365339 | H3: {=INDEX($A$3:$A$22, ROWS($H$3:H3))} -> AAPL.US | I3: =_xlfn.COVARIANCE.S( INDEX(Excess_Returns!$C$3:$V$62,0,MATCH($H3,Excess_Returns!$C$1:$V$1,0)), INDEX(Excess_Returns!$C$3:$V$62,0,MATCH(I$2,Excess_Returns!$C$1:$V$1,0)) ) -> 0.0070879096 | J3: =_xlfn.COVARIANCE.S( INDEX(Excess_Returns!$C$3:$V$62,0,MATCH($H3,Excess_Returns!$C$1:$V$1,0)), INDEX(Excess_Returns!$C$3:$V$62,0,MATCH(J$2,Excess_Returns!$C$1:$V$1,0)) ) -> 0.0037824466 | K3: =_xlfn.COVARIANCE.S( INDEX(Excess_Returns!$C$3:$V$62,0,MATCH($H3,Excess_Returns!$C$1:$V$1,0)), INDEX(Excess_Returns!$C$3:$V$62,0,MATCH(K$2,Excess_Returns!$C$1:$V$1,0)) ) -> 0.0034386396 | L3: =_xlfn.COVARIANCE.S( INDEX(Excess_Returns!$C$3:$V$62,0,MATCH($H3,Excess_Returns!$C$1:$V$1,0)), INDEX(Excess_Returns!$C$3:$V$62,0,MATCH(L$2,Excess_Returns!$C$1:$V$1,0)) ) -> 0.0063503388 | M3: =_xlfn.COVARIANCE.S( INDEX(Excess_Returns!$C$3:$V$62,0,MATCH($H3,Excess_Returns!$C$1:$V$1,0)), INDEX(Excess_Returns!$C$3:$V$62,0,MATCH(M$2,Excess_Returns!$C$1:$V$1,0)) ) -> 0.0039354667 | N3: =_xlfn.COVARIANCE.S( INDEX(Excess_Returns!$C$3:$V$62,0,MATCH($H3,Excess_Returns!$C$1:$V$1,0)), INDEX(Excess_Returns!$C$3:$V$62,0,MATCH(N$2,Excess_Returns!$C$1:$V$1,0)) ) -> 0.0017537674 | O3: =_xlfn.COVARIANCE.S( INDEX(Excess_Returns!$C$3:$V$62,0,MATCH($H3,Excess_Returns!$C$1:$V$1,0)), INDEX(Excess_Returns!$C$3:$V$62,0,MATCH(O$2,Excess_Returns!$C$1:$V$1,0)) ) -> 0.0022923078 | P3: =_xlfn.COVARIANCE.S( INDEX(Excess_Returns!$C$3:$V$62,0,MATCH($H3,Excess_Returns!$C$1:$V$1,0)), INDEX(Excess_Returns!$C$3:$V$62,0,MATCH(P$2,Excess_Returns!$C$1:$V$1,0)) ) -> 0.0019319127 | ... AB3: =_xlfn.COVARIANCE.S( INDEX(Excess_Returns!$C$3:$V$62,0,MATCH($H3,Excess_Returns!$C$1:$V$1,0)), INDEX(Excess_Returns!$C$3:$V$62,0,MATCH(AB$2,Excess_Returns!$C$1:$V$1,0)) ) -> 0.002752348
A4: MSFT.US | B4: =AVERAGE(Excess_Returns!D$2:D$62) -> 0.018018304 | C4: =_xlfn.STDEV.S(Excess_Returns!D2:D62) -> 0.064698174 | E4: =SLOPE(Excess_Returns!$C$3:$C$62,Excess_Returns!$B$3:$B$62) -> 1.2365339 | H4: {=INDEX($A$3:$A$22, ROWS($H$3:H4))} -> MSFT.US | I4: =_xlfn.COVARIANCE.S( INDEX(Excess_Returns!$C$3:$V$62,0,MATCH($H4,Excess_Returns!$C$1:$V$1,0)), INDEX(Excess_Returns!$C$3:$V$62,0,MATCH(I$2,Excess_Returns!$C$1:$V$1,0)) ) -> 0.0037824466 | J4: =_xlfn.COVARIANCE.S( INDEX(Excess_Returns!$C$3:$V$62,0,MATCH($H4,Excess_Returns!$C$1:$V$1,0)), INDEX(Excess_Returns!$C$3:$V$62,0,MATCH(J$2,Excess_Returns!$C$1:$V$1,0)) ) -> 0.0041858538 | K4: =_xlfn.COVARIANCE.S( INDEX(Excess_Returns!$C$3:$V$62,0,MATCH($H4,Excess_Returns!$C$1:$V$1,0)), INDEX(Excess_Returns!$C$3:$V$62,0,MATCH(K$2,Excess_Returns!$C$1:$V$1,0)) ) -> 0.0032723931 | L4: =_xlfn.COVARIANCE.S( INDEX(Excess_Returns!$C$3:$V$62,0,MATCH($H4,Excess_Returns!$C$1:$V$1,0)), INDEX(Excess_Returns!$C$3:$V$62,0,MATCH(L$2,Excess_Returns!$C$1:$V$1,0)) ) -> 0.0059219962 | M4: =_xlfn.COVARIANCE.S( INDEX(Excess_Returns!$C$3:$V$62,0,MATCH($H4,Excess_Returns!$C$1:$V$1,0)), INDEX(Excess_Returns!$C$3:$V$62,0,MATCH(M$2,Excess_Returns!$C$1:$V$1,0)) ) -> 0.0041896105 | N4: =_xlfn.COVARIANCE.S( INDEX(Excess_Returns!$C$3:$V$62,0,MATCH($H4,Excess_Returns!$C$1:$V$1,0)), INDEX(Excess_Returns!$C$3:$V$62,0,MATCH(N$2,Excess_Returns!$C$1:$V$1,0)) ) -> 0.0010112517 | O4: =_xlfn.COVARIANCE.S( INDEX(Excess_Returns!$C$3:$V$62,0,MATCH($H4,Excess_Returns!$C$1:$V$1,0)), INDEX(Excess_Returns!$C$3:$V$62,0,MATCH(O$2,Excess_Returns!$C$1:$V$1,0)) ) -> 0.0011617984 | P4: =_xlfn.COVARIANCE.S( INDEX(Excess_Returns!$C$3:$V$62,0,MATCH($H4,Excess_Returns!$C$1:$V$1,0)), INDEX(Excess_Returns!$C$3:$V$62,0,MATCH(P$2,Excess_Returns!$C$1:$V$1,0)) ) -> 0.0013398784 | ... AB4: =_xlfn.COVARIANCE.S( INDEX(Excess_Returns!$C$3:$V$62,0,MATCH($H4,Excess_Returns!$C$1:$V$1,0)), INDEX(Excess_Returns!$C$3:$V$62,0,MATCH(AB$2,Excess_Returns!$C$1:$V$1,0)) ) -> 0.001488617
A5: GOOGL.US | B5: =AVERAGE(Excess_Returns!E$2:E$62) -> 0.016917832 | C5: =_xlfn.STDEV.S(Excess_Returns!E2:E62) -> 0.076946642 | E5: =SLOPE(Excess_Returns!$C$3:$C$62,Excess_Returns!$B$3:$B$62) -> 1.2365339 | H5: {=INDEX($A$3:$A$22, ROWS($H$3:H5))} -> GOOGL.US | I5: =_xlfn.COVARIANCE.S( INDEX(Excess_Returns!$C$3:$V$62,0,MATCH($H5,Excess_Returns!$C$1:$V$1,0)), INDEX(Excess_Returns!$C$3:$V$62,0,MATCH(I$2,Excess_Returns!$C$1:$V$1,0)) ) -> 0.0034386396 | J5: =_xlfn.COVARIANCE.S( INDEX(Excess_Returns!$C$3:$V$62,0,MATCH($H5,Excess_Returns!$C$1:$V$1,0)), INDEX(Excess_Returns!$C$3:$V$62,0,MATCH(J$2,Excess_Returns!$C$1:$V$1,0)) ) -> 0.0032723931 | K5: =_xlfn.COVARIANCE.S( INDEX(Excess_Returns!$C$3:$V$62,0,MATCH($H5,Excess_Returns!$C$1:$V$1,0)), INDEX(Excess_Returns!$C$3:$V$62,0,MATCH(K$2,Excess_Returns!$C$1:$V$1,0)) ) -> 0.0059207857 | L5: =_xlfn.COVARIANCE.S( INDEX(Excess_Returns!$C$3:$V$62,0,MATCH($H5,Excess_Returns!$C$1:$V$1,0)), INDEX(Excess_Returns!$C$3:$V$62,0,MATCH(L$2,Excess_Returns!$C$1:$V$1,0)) ) -> 0.0062299412 | M5: =_xlfn.COVARIANCE.S( INDEX(Excess_Returns!$C$3:$V$62,0,MATCH($H5,Excess_Returns!$C$1:$V$1,0)), INDEX(Excess_Returns!$C$3:$V$62,0,MATCH(M$2,Excess_Returns!$C$1:$V$1,0)) ) -> 0.0041177747 | N5: =_xlfn.COVARIANCE.S( INDEX(Excess_Returns!$C$3:$V$62,0,MATCH($H5,Excess_Returns!$C$1:$V$1,0)), INDEX(Excess_Returns!$C$3:$V$62,0,MATCH(N$2,Excess_Returns!$C$1:$V$1,0)) ) -> 0.00065615945 | O5: =_xlfn.COVARIANCE.S( INDEX(Excess_Returns!$C$3:$V$62,0,MATCH($H5,Excess_Returns!$C$1:$V$1,0)), INDEX(Excess_Returns!$C$3:$V$62,0,MATCH(O$2,Excess_Returns!$C$1:$V$1,0)) ) -> 0.001623504 | P5: =_xlfn.COVARIANCE.S( INDEX(Excess_Returns!$C$3:$V$62,0,MATCH($H5,Excess_Returns!$C$1:$V$1,0)), INDEX(Excess_Returns!$C$3:$V$62,0,MATCH(P$2,Excess_Returns!$C$1:$V$1,0)) ) -> 0.0012042157 | ... AB5: =_xlfn.COVARIANCE.S( INDEX(Excess_Returns!$C$3:$V$62,0,MATCH($H5,Excess_Returns!$C$1:$V$1,0)), INDEX(Excess_Returns!$C$3:$V$62,0,MATCH(AB$2,Excess_Returns!$C$1:$V$1,0)) ) -> 0.0014496785
A6: NVDA.US | B6: =AVERAGE(Excess_Returns!F$2:F$62) -> 0.063391183 | C6: =_xlfn.STDEV.S(Excess_Returns!F2:F62) -> 0.14316794 | E6: =SLOPE(Excess_Returns!$C$3:$C$62,Excess_Returns!$B$3:$B$62) -> 1.2365339 | H6: {=INDEX($A$3:$A$22, ROWS($H$3:H6))} -> NVDA.US | I6: =_xlfn.COVARIANCE.S( INDEX(Excess_Returns!$C$3:$V$62,0,MATCH($H6,Excess_Returns!$C$1:$V$1,0)), INDEX(Excess_Returns!$C$3:$V$62,0,MATCH(I$2,Excess_Returns!$C$1:$V$1,0)) ) -> 0.0063503388 | J6: =_xlfn.COVARIANCE.S( INDEX(Excess_Returns!$C$3:$V$62,0,MATCH($H6,Excess_Returns!$C$1:$V$1,0)), INDEX(Excess_Returns!$C$3:$V$62,0,MATCH(J$2,Excess_Returns!$C$1:$V$1,0)) ) -> 0.0059219962 | K6: =_xlfn.COVARIANCE.S( INDEX(Excess_Returns!$C$3:$V$62,0,MATCH($H6,Excess_Returns!$C$1:$V$1,0)), INDEX(Excess_Returns!$C$3:$V$62,0,MATCH(K$2,Excess_Returns!$C$1:$V$1,0)) ) -> 0.0062299412 | L6: =_xlfn.COVARIANCE.S( INDEX(Excess_Returns!$C$3:$V$62,0,MATCH($H6,Excess_Returns!$C$1:$V$1,0)), INDEX(Excess_Returns!$C$3:$V$62,0,MATCH(L$2,Excess_Returns!$C$1:$V$1,0)) ) -> 0.020497058 | M6: =_xlfn.COVARIANCE.S( INDEX(Excess_Returns!$C$3:$V$62,0,MATCH($H6,Excess_Returns!$C$1:$V$1,0)), INDEX(Excess_Returns!$C$3:$V$62,0,MATCH(M$2,Excess_Returns!$C$1:$V$1,0)) ) -> 0.0089615173 | N6: =_xlfn.COVARIANCE.S( INDEX(Excess_Returns!$C$3:$V$62,0,MATCH($H6,Excess_Returns!$C$1:$V$1,0)), INDEX(Excess_Returns!$C$3:$V$62,0,MATCH(N$2,Excess_Returns!$C$1:$V$1,0)) ) -> -7.0311131e-05 | O6: =_xlfn.COVARIANCE.S( INDEX(Excess_Returns!$C$3:$V$62,0,MATCH($H6,Excess_Returns!$C$1:$V$1,0)), INDEX(Excess_Returns!$C$3:$V$62,0,MATCH(O$2,Excess_Returns!$C$1:$V$1,0)) ) -> 0.0023945424 | P6: =_xlfn.COVARIANCE.S( INDEX(Excess_Returns!$C$3:$V$62,0,MATCH($H6,Excess_Returns!$C$1:$V$1,0)), INDEX(Excess_Returns!$C$3:$V$62,0,MATCH(P$2,Excess_Returns!$C$1:$V$1,0)) ) -> -3.1129229e-05 | ... AB6: =_xlfn.COVARIANCE.S( INDEX(Excess_Returns!$C$3:$V$62,0,MATCH($H6,Excess_Returns!$C$1:$V$1,0)), INDEX(Excess_Returns!$C$3:$V$62,0,MATCH(AB$2,Excess_Returns!$C$1:$V$1,0)) ) -> 0.0011945656
A7: META.US | B7: =AVERAGE(Excess_Returns!G$2:G$62) -> 0.022760691 | C7: =_xlfn.STDEV.S(Excess_Returns!G2:G62) -> 0.1182377 | E7: =SLOPE(Excess_Returns!$C$3:$C$62,Excess_Returns!$B$3:$B$62) -> 1.2365339 | H7: {=INDEX($A$3:$A$22, ROWS($H$3:H7))} -> META.US | I7: =_xlfn.COVARIANCE.S( INDEX(Excess_Returns!$C$3:$V$62,0,MATCH($H7,Excess_Returns!$C$1:$V$1,0)), INDEX(Excess_Returns!$C$3:$V$62,0,MATCH(I$2,Excess_Returns!$C$1:$V$1,0)) ) -> 0.0039354667 | J7: =_xlfn.COVARIANCE.S( INDEX(Excess_Returns!$C$3:$V$62,0,MATCH($H7,Excess_Returns!$C$1:$V$1,0)), INDEX(Excess_Returns!$C$3:$V$62,0,MATCH(J$2,Excess_Returns!$C$1:$V$1,0)) ) -> 0.0041896105 | K7: =_xlfn.COVARIANCE.S( INDEX(Excess_Returns!$C$3:$V$62,0,MATCH($H7,Excess_Returns!$C$1:$V$1,0)), INDEX(Excess_Returns!$C$3:$V$62,0,MATCH(K$2,Excess_Returns!$C$1:$V$1,0)) ) -> 0.0041177747 | L7: =_xlfn.COVARIANCE.S( INDEX(Excess_Returns!$C$3:$V$62,0,MATCH($H7,Excess_Returns!$C$1:$V$1,0)), INDEX(Excess_Returns!$C$3:$V$62,0,MATCH(L$2,Excess_Returns!$C$1:$V$1,0)) ) -> 0.0089615173 | M7: =_xlfn.COVARIANCE.S( INDEX(Excess_Returns!$C$3:$V$62,0,MATCH($H7,Excess_Returns!$C$1:$V$1,0)), INDEX(Excess_Returns!$C$3:$V$62,0,MATCH(M$2,Excess_Returns!$C$1:$V$1,0)) ) -> 0.013980154 | N7: =_xlfn.COVARIANCE.S( INDEX(Excess_Returns!$C$3:$V$62,0,MATCH($H7,Excess_Returns!$C$1:$V$1,0)), INDEX(Excess_Returns!$C$3:$V$62,0,MATCH(N$2,Excess_Returns!$C$1:$V$1,0)) ) -> 0.0011393419 | O7: =_xlfn.COVARIANCE.S( INDEX(Excess_Returns!$C$3:$V$62,0,MATCH($H7,Excess_Returns!$C$1:$V$1,0)), INDEX(Excess_Returns!$C$3:$V$62,0,MATCH(O$2,Excess_Returns!$C$1:$V$1,0)) ) -> 0.0017741357 | P7: =_xlfn.COVARIANCE.S( INDEX(Excess_Returns!$C$3:$V$62,0,MATCH($H7,Excess_Returns!$C$1:$V$1,0)), INDEX(Excess_Returns!$C$3:$V$62,0,MATCH(P$2,Excess_Returns!$C$1:$V$1,0)) ) -> 0.00030513249 | ... AB7: =_xlfn.COVARIANCE.S( INDEX(Excess_Returns!$C$3:$V$62,0,MATCH($H7,Excess_Returns!$C$1:$V$1,0)), INDEX(Excess_Returns!$C$3:$V$62,0,MATCH(AB$2,Excess_Returns!$C$1:$V$1,0)) ) -> 0.0016348892
A8: JNJ.US | B8: =AVERAGE(Excess_Returns!H$2:H$62) -> 0.002481011 | C8: =_xlfn.STDEV.S(Excess_Returns!H2:H62) -> 0.050403689 | E8: =SLOPE(Excess_Returns!$C$3:$C$62,Excess_Returns!$B$3:$B$62) -> 1.2365339 | H8: {=INDEX($A$3:$A$22, ROWS($H$3:H8))} -> JNJ.US | I8: =_xlfn.COVARIANCE.S( INDEX(Excess_Returns!$C$3:$V$62,0,MATCH($H8,Excess_Returns!$C$1:$V$1,0)), INDEX(Excess_Returns!$C$3:$V$62,0,MATCH(I$2,Excess_Returns!$C$1:$V$1,0)) ) -> 0.0017537674 | J8: =_xlfn.COVARIANCE.S( INDEX(Excess_Returns!$C$3:$V$62,0,MATCH($H8,Excess_Returns!$C$1:$V$1,0)), INDEX(Excess_Returns!$C$3:$V$62,0,MATCH(J$2,Excess_Returns!$C$1:$V$1,0)) ) -> 0.0010112517 | K8: =_xlfn.COVARIANCE.S( INDEX(Excess_Returns!$C$3:$V$62,0,MATCH($H8,Excess_Returns!$C$1:$V$1,0)), INDEX(Excess_Returns!$C$3:$V$62,0,MATCH(K$2,Excess_Returns!$C$1:$V$1,0)) ) -> 0.00065615945 | L8: =_xlfn.COVARIANCE.S( INDEX(Excess_Returns!$C$3:$V$62,0,MATCH($H8,Excess_Returns!$C$1:$V$1,0)), INDEX(Excess_Returns!$C$3:$V$62,0,MATCH(L$2,Excess_Returns!$C$1:$V$1,0)) ) -> -7.0311131e-05 | M8: =_xlfn.COVARIANCE.S( INDEX(Excess_Returns!$C$3:$V$62,0,MATCH($H8,Excess_Returns!$C$1:$V$1,0)), INDEX(Excess_Returns!$C$3:$V$62,0,MATCH(M$2,Excess_Returns!$C$1:$V$1,0)) ) -> 0.0011393419 | N8: =_xlfn.COVARIANCE.S( INDEX(Excess_Returns!$C$3:$V$62,0,MATCH($H8,Excess_Returns!$C$1:$V$1,0)), INDEX(Excess_Returns!$C$3:$V$62,0,MATCH(N$2,Excess_Returns!$C$1:$V$1,0)) ) -> 0.0025405319 | O8: =_xlfn.COVARIANCE.S( INDEX(Excess_Returns!$C$3:$V$62,0,MATCH($H8,Excess_Returns!$C$1:$V$1,0)), INDEX(Excess_Returns!$C$3:$V$62,0,MATCH(O$2,Excess_Returns!$C$1:$V$1,0)) ) -> 0.0021998074 | P8: =_xlfn.COVARIANCE.S( INDEX(Excess_Returns!$C$3:$V$62,0,MATCH($H8,Excess_Returns!$C$1:$V$1,0)), INDEX(Excess_Returns!$C$3:$V$62,0,MATCH(P$2,Excess_Returns!$C$1:$V$1,0)) ) -> 0.00175861 | ... AB8: =_xlfn.COVARIANCE.S( INDEX(Excess_Returns!$C$3:$V$62,0,MATCH($H8,Excess_Returns!$C$1:$V$1,0)), INDEX(Excess_Returns!$C$3:$V$62,0,MATCH(AB$2,Excess_Returns!$C$1:$V$1,0)) ) -> 0.0016543532
A9: PFE.US | B9: =AVERAGE(Excess_Returns!I$2:I$62) -> -0.0036473317 | C9: =_xlfn.STDEV.S(Excess_Returns!I2:I62) -> 0.079301851 | E9: =SLOPE(Excess_Returns!$C$3:$C$62,Excess_Returns!$B$3:$B$62) -> 1.2365339 | H9: {=INDEX($A$3:$A$22, ROWS($H$3:H9))} -> PFE.US | I9: =_xlfn.COVARIANCE.S( INDEX(Excess_Returns!$C$3:$V$62,0,MATCH($H9,Excess_Returns!$C$1:$V$1,0)), INDEX(Excess_Returns!$C$3:$V$62,0,MATCH(I$2,Excess_Returns!$C$1:$V$1,0)) ) -> 0.0022923078 | J9: =_xlfn.COVARIANCE.S( INDEX(Excess_Returns!$C$3:$V$62,0,MATCH($H9,Excess_Returns!$C$1:$V$1,0)), INDEX(Excess_Returns!$C$3:$V$62,0,MATCH(J$2,Excess_Returns!$C$1:$V$1,0)) ) -> 0.0011617984 | K9: =_xlfn.COVARIANCE.S( INDEX(Excess_Returns!$C$3:$V$62,0,MATCH($H9,Excess_Returns!$C$1:$V$1,0)), INDEX(Excess_Returns!$C$3:$V$62,0,MATCH(K$2,Excess_Returns!$C$1:$V$1,0)) ) -> 0.001623504 | L9: =_xlfn.COVARIANCE.S( INDEX(Excess_Returns!$C$3:$V$62,0,MATCH($H9,Excess_Returns!$C$1:$V$1,0)), INDEX(Excess_Returns!$C$3:$V$62,0,MATCH(L$2,Excess_Returns!$C$1:$V$1,0)) ) -> 0.0023945424 | M9: =_xlfn.COVARIANCE.S( INDEX(Excess_Returns!$C$3:$V$62,0,MATCH($H9,Excess_Returns!$C$1:$V$1,0)), INDEX(Excess_Returns!$C$3:$V$62,0,MATCH(M$2,Excess_Returns!$C$1:$V$1,0)) ) -> 0.0017741357 | N9: =_xlfn.COVARIANCE.S( INDEX(Excess_Returns!$C$3:$V$62,0,MATCH($H9,Excess_Returns!$C$1:$V$1,0)), INDEX(Excess_Returns!$C$3:$V$62,0,MATCH(N$2,Excess_Returns!$C$1:$V$1,0)) ) -> 0.0021998074 | O9: =_xlfn.COVARIANCE.S( INDEX(Excess_Returns!$C$3:$V$62,0,MATCH($H9,Excess_Returns!$C$1:$V$1,0)), INDEX(Excess_Returns!$C$3:$V$62,0,MATCH(O$2,Excess_Returns!$C$1:$V$1,0)) ) -> 0.0062887835 | P9: =_xlfn.COVARIANCE.S( INDEX(Excess_Returns!$C$3:$V$62,0,MATCH($H9,Excess_Returns!$C$1:$V$1,0)), INDEX(Excess_Returns!$C$3:$V$62,0,MATCH(P$2,Excess_Returns!$C$1:$V$1,0)) ) -> 0.0021958095 | ... AB9: =_xlfn.COVARIANCE.S( INDEX(Excess_Returns!$C$3:$V$62,0,MATCH($H9,Excess_Returns!$C$1:$V$1,0)), INDEX(Excess_Returns!$C$3:$V$62,0,MATCH(AB$2,Excess_Returns!$C$1:$V$1,0)) ) -> 0.0016676871
A10: UNH.US | B10: =AVERAGE(Excess_Returns!J$2:J$62) -> 0.013925248 | C10: =_xlfn.STDEV.S(Excess_Returns!J2:J62) -> 0.05949158 | E10: =SLOPE(Excess_Returns!$C$3:$C$62,Excess_Returns!$B$3:$B$62) -> 1.2365339 | H10: {=INDEX($A$3:$A$22, ROWS($H$3:H10))} -> UNH.US | I10: =_xlfn.COVARIANCE.S( INDEX(Excess_Returns!$C$3:$V$62,0,MATCH($H10,Excess_Returns!$C$1:$V$1,0)), INDEX(Excess_Returns!$C$3:$V$62,0,MATCH(I$2,Excess_Returns!$C$1:$V$1,0)) ) -> 0.0019319127 | J10: =_xlfn.COVARIANCE.S( INDEX(Excess_Returns!$C$3:$V$62,0,MATCH($H10,Excess_Returns!$C$1:$V$1,0)), INDEX(Excess_Returns!$C$3:$V$62,0,MATCH(J$2,Excess_Returns!$C$1:$V$1,0)) ) -> 0.0013398784 | K10: =_xlfn.COVARIANCE.S( INDEX(Excess_Returns!$C$3:$V$62,0,MATCH($H10,Excess_Returns!$C$1:$V$1,0)), INDEX(Excess_Returns!$C$3:$V$62,0,MATCH(K$2,Excess_Returns!$C$1:$V$1,0)) ) -> 0.0012042157 | L10: =_xlfn.COVARIANCE.S( INDEX(Excess_Returns!$C$3:$V$62,0,MATCH($H10,Excess_Returns!$C$1:$V$1,0)), INDEX(Excess_Returns!$C$3:$V$62,0,MATCH(L$2,Excess_Returns!$C$1:$V$1,0)) ) -> -3.1129229e-05 | M10: =_xlfn.COVARIANCE.S( INDEX(Excess_Returns!$C$3:$V$62,0,MATCH($H10,Excess_Returns!$C$1:$V$1,0)), INDEX(Excess_Returns!$C$3:$V$62,0,MATCH(M$2,Excess_Returns!$C$1:$V$1,0)) ) -> 0.00030513249 | N10: =_xlfn.COVARIANCE.S( INDEX(Excess_Returns!$C$3:$V$62,0,MATCH($H10,Excess_Returns!$C$1:$V$1,0)), INDEX(Excess_Returns!$C$3:$V$62,0,MATCH(N$2,Excess_Returns!$C$1:$V$1,0)) ) -> 0.00175861 | O10: =_xlfn.COVARIANCE.S( INDEX(Excess_Returns!$C$3:$V$62,0,MATCH($H10,Excess_Returns!$C$1:$V$1,0)), INDEX(Excess_Returns!$C$3:$V$62,0,MATCH(O$2,Excess_Returns!$C$1:$V$1,0)) ) -> 0.0021958095 | P10: =_xlfn.COVARIANCE.S( INDEX(Excess_Returns!$C$3:$V$62,0,MATCH($H10,Excess_Returns!$C$1:$V$1,0)), INDEX(Excess_Returns!$C$3:$V$62,0,MATCH(P$2,Excess_Returns!$C$1:$V$1,0)) ) -> 0.0035392481 | ... AB10: =_xlfn.COVARIANCE.S( INDEX(Excess_Returns!$C$3:$V$62,0,MATCH($H10,Excess_Returns!$C$1:$V$1,0)), INDEX(Excess_Returns!$C$3:$V$62,0,MATCH(AB$2,Excess_Returns!$C$1:$V$1,0)) ) -> 0.0016076724
A11: MRK.US | B11: =AVERAGE(Excess_Returns!K$2:K$62) -> 0.0049840274 | C11: =_xlfn.STDEV.S(Excess_Returns!K2:K62) -> 0.062855963 | E11: =SLOPE(Excess_Returns!$C$3:$C$62,Excess_Returns!$B$3:$B$62) -> 1.2365339 | H11: {=INDEX($A$3:$A$22, ROWS($H$3:H11))} -> MRK.US | I11: =_xlfn.COVARIANCE.S( INDEX(Excess_Returns!$C$3:$V$62,0,MATCH($H11,Excess_Returns!$C$1:$V$1,0)), INDEX(Excess_Returns!$C$3:$V$62,0,MATCH(I$2,Excess_Returns!$C$1:$V$1,0)) ) -> 0.00071925051 | J11: =_xlfn.COVARIANCE.S( INDEX(Excess_Returns!$C$3:$V$62,0,MATCH($H11,Excess_Returns!$C$1:$V$1,0)), INDEX(Excess_Returns!$C$3:$V$62,0,MATCH(J$2,Excess_Returns!$C$1:$V$1,0)) ) -> 0.0010521872 | K11: =_xlfn.COVARIANCE.S( INDEX(Excess_Returns!$C$3:$V$62,0,MATCH($H11,Excess_Returns!$C$1:$V$1,0)), INDEX(Excess_Returns!$C$3:$V$62,0,MATCH(K$2,Excess_Returns!$C$1:$V$1,0)) ) -> -5.0397633e-05 | L11: =_xlfn.COVARIANCE.S( INDEX(Excess_Returns!$C$3:$V$62,0,MATCH($H11,Excess_Returns!$C$1:$V$1,0)), INDEX(Excess_Returns!$C$3:$V$62,0,MATCH(L$2,Excess_Returns!$C$1:$V$1,0)) ) -> 0.00037279364 | M11: =_xlfn.COVARIANCE.S( INDEX(Excess_Returns!$C$3:$V$62,0,MATCH($H11,Excess_Returns!$C$1:$V$1,0)), INDEX(Excess_Returns!$C$3:$V$62,0,MATCH(M$2,Excess_Returns!$C$1:$V$1,0)) ) -> 0.00049295683 | N11: =_xlfn.COVARIANCE.S( INDEX(Excess_Returns!$C$3:$V$62,0,MATCH($H11,Excess_Returns!$C$1:$V$1,0)), INDEX(Excess_Returns!$C$3:$V$62,0,MATCH(N$2,Excess_Returns!$C$1:$V$1,0)) ) -> 0.0015497973 | O11: =_xlfn.COVARIANCE.S( INDEX(Excess_Returns!$C$3:$V$62,0,MATCH($H11,Excess_Returns!$C$1:$V$1,0)), INDEX(Excess_Returns!$C$3:$V$62,0,MATCH(O$2,Excess_Returns!$C$1:$V$1,0)) ) -> 0.00064809978 | P11: =_xlfn.COVARIANCE.S( INDEX(Excess_Returns!$C$3:$V$62,0,MATCH($H11,Excess_Returns!$C$1:$V$1,0)), INDEX(Excess_Returns!$C$3:$V$62,0,MATCH(P$2,Excess_Returns!$C$1:$V$1,0)) ) -> 0.0013014964 | ... AB11: =_xlfn.COVARIANCE.S( INDEX(Excess_Returns!$C$3:$V$62,0,MATCH($H11,Excess_Returns!$C$1:$V$1,0)), INDEX(Excess_Returns!$C$3:$V$62,0,MATCH(AB$2,Excess_Returns!$C$1:$V$1,0)) ) -> 0.0013310303
A12: ABBV.US | B12: =AVERAGE(Excess_Returns!L$2:L$62) -> 0.015017195 | C12: =_xlfn.STDEV.S(Excess_Returns!L2:L62) -> 0.070640958 | E12: =SLOPE(Excess_Returns!$C$3:$C$62,Excess_Returns!$B$3:$B$62) -> 1.2365339 | H12: {=INDEX($A$3:$A$22, ROWS($H$3:H12))} -> ABBV.US | I12: =_xlfn.COVARIANCE.S( INDEX(Excess_Returns!$C$3:$V$62,0,MATCH($H12,Excess_Returns!$C$1:$V$1,0)), INDEX(Excess_Returns!$C$3:$V$62,0,MATCH(I$2,Excess_Returns!$C$1:$V$1,0)) ) -> 0.0011202053 | J12: =_xlfn.COVARIANCE.S( INDEX(Excess_Returns!$C$3:$V$62,0,MATCH($H12,Excess_Returns!$C$1:$V$1,0)), INDEX(Excess_Returns!$C$3:$V$62,0,MATCH(J$2,Excess_Returns!$C$1:$V$1,0)) ) -> 0.00099543026 | K12: =_xlfn.COVARIANCE.S( INDEX(Excess_Returns!$C$3:$V$62,0,MATCH($H12,Excess_Returns!$C$1:$V$1,0)), INDEX(Excess_Returns!$C$3:$V$62,0,MATCH(K$2,Excess_Returns!$C$1:$V$1,0)) ) -> 0.0014256921 | L12: =_xlfn.COVARIANCE.S( INDEX(Excess_Returns!$C$3:$V$62,0,MATCH($H12,Excess_Returns!$C$1:$V$1,0)), INDEX(Excess_Returns!$C$3:$V$62,0,MATCH(L$2,Excess_Returns!$C$1:$V$1,0)) ) -> 0.0017929498 | M12: =_xlfn.COVARIANCE.S( INDEX(Excess_Returns!$C$3:$V$62,0,MATCH($H12,Excess_Returns!$C$1:$V$1,0)), INDEX(Excess_Returns!$C$3:$V$62,0,MATCH(M$2,Excess_Returns!$C$1:$V$1,0)) ) -> 0.0013171843 | N12: =_xlfn.COVARIANCE.S( INDEX(Excess_Returns!$C$3:$V$62,0,MATCH($H12,Excess_Returns!$C$1:$V$1,0)), INDEX(Excess_Returns!$C$3:$V$62,0,MATCH(N$2,Excess_Returns!$C$1:$V$1,0)) ) -> 0.0016649285 | O12: =_xlfn.COVARIANCE.S( INDEX(Excess_Returns!$C$3:$V$62,0,MATCH($H12,Excess_Returns!$C$1:$V$1,0)), INDEX(Excess_Returns!$C$3:$V$62,0,MATCH(O$2,Excess_Returns!$C$1:$V$1,0)) ) -> 0.0020478259 | P12: =_xlfn.COVARIANCE.S( INDEX(Excess_Returns!$C$3:$V$62,0,MATCH($H12,Excess_Returns!$C$1:$V$1,0)), INDEX(Excess_Returns!$C$3:$V$62,0,MATCH(P$2,Excess_Returns!$C$1:$V$1,0)) ) -> 0.0018037473 | ... AB12: =_xlfn.COVARIANCE.S( INDEX(Excess_Returns!$C$3:$V$62,0,MATCH($H12,Excess_Returns!$C$1:$V$1,0)), INDEX(Excess_Returns!$C$3:$V$62,0,MATCH(AB$2,Excess_Returns!$C$1:$V$1,0)) ) -> 0.00093339226
A13: XOM.US | B13: =AVERAGE(Excess_Returns!M$2:M$62) -> 0.0147693 | C13: =_xlfn.STDEV.S(Excess_Returns!M2:M62) -> 0.098390262 | E13: =SLOPE(Excess_Returns!$C$3:$C$62,Excess_Returns!$B$3:$B$62) -> 1.2365339 | H13: {=INDEX($A$3:$A$22, ROWS($H$3:H13))} -> XOM.US | I13: =_xlfn.COVARIANCE.S( INDEX(Excess_Returns!$C$3:$V$62,0,MATCH($H13,Excess_Returns!$C$1:$V$1,0)), INDEX(Excess_Returns!$C$3:$V$62,0,MATCH(I$2,Excess_Returns!$C$1:$V$1,0)) ) -> 0.0016164836 | J13: =_xlfn.COVARIANCE.S( INDEX(Excess_Returns!$C$3:$V$62,0,MATCH($H13,Excess_Returns!$C$1:$V$1,0)), INDEX(Excess_Returns!$C$3:$V$62,0,MATCH(J$2,Excess_Returns!$C$1:$V$1,0)) ) -> 0.00079673429 | K13: =_xlfn.COVARIANCE.S( INDEX(Excess_Returns!$C$3:$V$62,0,MATCH($H13,Excess_Returns!$C$1:$V$1,0)), INDEX(Excess_Returns!$C$3:$V$62,0,MATCH(K$2,Excess_Returns!$C$1:$V$1,0)) ) -> 0.0018543944 | L13: =_xlfn.COVARIANCE.S( INDEX(Excess_Returns!$C$3:$V$62,0,MATCH($H13,Excess_Returns!$C$1:$V$1,0)), INDEX(Excess_Returns!$C$3:$V$62,0,MATCH(L$2,Excess_Returns!$C$1:$V$1,0)) ) -> 5.1333035e-05 | M13: =_xlfn.COVARIANCE.S( INDEX(Excess_Returns!$C$3:$V$62,0,MATCH($H13,Excess_Returns!$C$1:$V$1,0)), INDEX(Excess_Returns!$C$3:$V$62,0,MATCH(M$2,Excess_Returns!$C$1:$V$1,0)) ) -> -0.00035287721 | N13: =_xlfn.COVARIANCE.S( INDEX(Excess_Returns!$C$3:$V$62,0,MATCH($H13,Excess_Returns!$C$1:$V$1,0)), INDEX(Excess_Returns!$C$3:$V$62,0,MATCH(N$2,Excess_Returns!$C$1:$V$1,0)) ) -> 0.0017286383 | O13: =_xlfn.COVARIANCE.S( INDEX(Excess_Returns!$C$3:$V$62,0,MATCH($H13,Excess_Returns!$C$1:$V$1,0)), INDEX(Excess_Returns!$C$3:$V$62,0,MATCH(O$2,Excess_Returns!$C$1:$V$1,0)) ) -> 0.00090202994 | P13: =_xlfn.COVARIANCE.S( INDEX(Excess_Returns!$C$3:$V$62,0,MATCH($H13,Excess_Returns!$C$1:$V$1,0)), INDEX(Excess_Returns!$C$3:$V$62,0,MATCH(P$2,Excess_Returns!$C$1:$V$1,0)) ) -> 0.0018074404 | ... AB13: =_xlfn.COVARIANCE.S( INDEX(Excess_Returns!$C$3:$V$62,0,MATCH($H13,Excess_Returns!$C$1:$V$1,0)), INDEX(Excess_Returns!$C$3:$V$62,0,MATCH(AB$2,Excess_Returns!$C$1:$V$1,0)) ) -> 0.002091572
A14: CVX.US | B14: =AVERAGE(Excess_Returns!N$2:N$62) -> 0.010201658 | C14: =_xlfn.STDEV.S(Excess_Returns!N2:N62) -> 0.096930882 | E14: =SLOPE(Excess_Returns!$C$3:$C$62,Excess_Returns!$B$3:$B$62) -> 1.2365339 | H14: {=INDEX($A$3:$A$22, ROWS($H$3:H14))} -> CVX.US | I14: =_xlfn.COVARIANCE.S( INDEX(Excess_Returns!$C$3:$V$62,0,MATCH($H14,Excess_Returns!$C$1:$V$1,0)), INDEX(Excess_Returns!$C$3:$V$62,0,MATCH(I$2,Excess_Returns!$C$1:$V$1,0)) ) -> 0.0023204324 | J14: =_xlfn.COVARIANCE.S( INDEX(Excess_Returns!$C$3:$V$62,0,MATCH($H14,Excess_Returns!$C$1:$V$1,0)), INDEX(Excess_Returns!$C$3:$V$62,0,MATCH(J$2,Excess_Returns!$C$1:$V$1,0)) ) -> 0.0013613612 | K14: =_xlfn.COVARIANCE.S( INDEX(Excess_Returns!$C$3:$V$62,0,MATCH($H14,Excess_Returns!$C$1:$V$1,0)), INDEX(Excess_Returns!$C$3:$V$62,0,MATCH(K$2,Excess_Returns!$C$1:$V$1,0)) ) -> 0.0026431359 | L14: =_xlfn.COVARIANCE.S( INDEX(Excess_Returns!$C$3:$V$62,0,MATCH($H14,Excess_Returns!$C$1:$V$1,0)), INDEX(Excess_Returns!$C$3:$V$62,0,MATCH(L$2,Excess_Returns!$C$1:$V$1,0)) ) -> 0.0017063606 | M14: =_xlfn.COVARIANCE.S( INDEX(Excess_Returns!$C$3:$V$62,0,MATCH($H14,Excess_Returns!$C$1:$V$1,0)), INDEX(Excess_Returns!$C$3:$V$62,0,MATCH(M$2,Excess_Returns!$C$1:$V$1,0)) ) -> 0.00010885563 | N14: =_xlfn.COVARIANCE.S( INDEX(Excess_Returns!$C$3:$V$62,0,MATCH($H14,Excess_Returns!$C$1:$V$1,0)), INDEX(Excess_Returns!$C$3:$V$62,0,MATCH(N$2,Excess_Returns!$C$1:$V$1,0)) ) -> 0.0019449231 | O14: =_xlfn.COVARIANCE.S( INDEX(Excess_Returns!$C$3:$V$62,0,MATCH($H14,Excess_Returns!$C$1:$V$1,0)), INDEX(Excess_Returns!$C$3:$V$62,0,MATCH(O$2,Excess_Returns!$C$1:$V$1,0)) ) -> 0.0020992906 | P14: =_xlfn.COVARIANCE.S( INDEX(Excess_Returns!$C$3:$V$62,0,MATCH($H14,Excess_Returns!$C$1:$V$1,0)), INDEX(Excess_Returns!$C$3:$V$62,0,MATCH(P$2,Excess_Returns!$C$1:$V$1,0)) ) -> 0.0026112086 | ... AB14: =_xlfn.COVARIANCE.S( INDEX(Excess_Returns!$C$3:$V$62,0,MATCH($H14,Excess_Returns!$C$1:$V$1,0)), INDEX(Excess_Returns!$C$3:$V$62,0,MATCH(AB$2,Excess_Returns!$C$1:$V$1,0)) ) -> 0.0023920617
A15: COP.US | B15: =AVERAGE(Excess_Returns!O$2:O$62) -> 0.017545654 | C15: =_xlfn.STDEV.S(Excess_Returns!O2:O62) -> 0.12803189 | E15: =SLOPE(Excess_Returns!$C$3:$C$62,Excess_Returns!$B$3:$B$62) -> 1.2365339 | H15: {=INDEX($A$3:$A$22, ROWS($H$3:H15))} -> COP.US | I15: =_xlfn.COVARIANCE.S( INDEX(Excess_Returns!$C$3:$V$62,0,MATCH($H15,Excess_Returns!$C$1:$V$1,0)), INDEX(Excess_Returns!$C$3:$V$62,0,MATCH(I$2,Excess_Returns!$C$1:$V$1,0)) ) -> 0.0020020092 | J15: =_xlfn.COVARIANCE.S( INDEX(Excess_Returns!$C$3:$V$62,0,MATCH($H15,Excess_Returns!$C$1:$V$1,0)), INDEX(Excess_Returns!$C$3:$V$62,0,MATCH(J$2,Excess_Returns!$C$1:$V$1,0)) ) -> 0.0011241479 | K15: =_xlfn.COVARIANCE.S( INDEX(Excess_Returns!$C$3:$V$62,0,MATCH($H15,Excess_Returns!$C$1:$V$1,0)), INDEX(Excess_Returns!$C$3:$V$62,0,MATCH(K$2,Excess_Returns!$C$1:$V$1,0)) ) -> 0.0030539485 | L15: =_xlfn.COVARIANCE.S( INDEX(Excess_Returns!$C$3:$V$62,0,MATCH($H15,Excess_Returns!$C$1:$V$1,0)), INDEX(Excess_Returns!$C$3:$V$62,0,MATCH(L$2,Excess_Returns!$C$1:$V$1,0)) ) -> 0.00073171866 | M15: =_xlfn.COVARIANCE.S( INDEX(Excess_Returns!$C$3:$V$62,0,MATCH($H15,Excess_Returns!$C$1:$V$1,0)), INDEX(Excess_Returns!$C$3:$V$62,0,MATCH(M$2,Excess_Returns!$C$1:$V$1,0)) ) -> 0.0003054017 | N15: =_xlfn.COVARIANCE.S( INDEX(Excess_Returns!$C$3:$V$62,0,MATCH($H15,Excess_Returns!$C$1:$V$1,0)), INDEX(Excess_Returns!$C$3:$V$62,0,MATCH(N$2,Excess_Returns!$C$1:$V$1,0)) ) -> 0.0020394337 | O15: =_xlfn.COVARIANCE.S( INDEX(Excess_Returns!$C$3:$V$62,0,MATCH($H15,Excess_Returns!$C$1:$V$1,0)), INDEX(Excess_Returns!$C$3:$V$62,0,MATCH(O$2,Excess_Returns!$C$1:$V$1,0)) ) -> 0.0012627411 | P15: =_xlfn.COVARIANCE.S( INDEX(Excess_Returns!$C$3:$V$62,0,MATCH($H15,Excess_Returns!$C$1:$V$1,0)), INDEX(Excess_Returns!$C$3:$V$62,0,MATCH(P$2,Excess_Returns!$C$1:$V$1,0)) ) -> 0.0023427401 | ... AB15: =_xlfn.COVARIANCE.S( INDEX(Excess_Returns!$C$3:$V$62,0,MATCH($H15,Excess_Returns!$C$1:$V$1,0)), INDEX(Excess_Returns!$C$3:$V$62,0,MATCH(AB$2,Excess_Returns!$C$1:$V$1,0)) ) -> 0.0025716244
A16: SLB.US | B16: =AVERAGE(Excess_Returns!P$2:P$62) -> 0.013419479 | C16: =_xlfn.STDEV.S(Excess_Returns!P2:P62) -> 0.14595209 | E16: =SLOPE(Excess_Returns!$C$3:$C$62,Excess_Returns!$B$3:$B$62) -> 1.2365339 | H16: {=INDEX($A$3:$A$22, ROWS($H$3:H16))} -> SLB.US | I16: =_xlfn.COVARIANCE.S( INDEX(Excess_Returns!$C$3:$V$62,0,MATCH($H16,Excess_Returns!$C$1:$V$1,0)), INDEX(Excess_Returns!$C$3:$V$62,0,MATCH(I$2,Excess_Returns!$C$1:$V$1,0)) ) -> 0.0031402235 | J16: =_xlfn.COVARIANCE.S( INDEX(Excess_Returns!$C$3:$V$62,0,MATCH($H16,Excess_Returns!$C$1:$V$1,0)), INDEX(Excess_Returns!$C$3:$V$62,0,MATCH(J$2,Excess_Returns!$C$1:$V$1,0)) ) -> 0.0010889795 | K16: =_xlfn.COVARIANCE.S( INDEX(Excess_Returns!$C$3:$V$62,0,MATCH($H16,Excess_Returns!$C$1:$V$1,0)), INDEX(Excess_Returns!$C$3:$V$62,0,MATCH(K$2,Excess_Returns!$C$1:$V$1,0)) ) -> 0.0029221434 | L16: =_xlfn.COVARIANCE.S( INDEX(Excess_Returns!$C$3:$V$62,0,MATCH($H16,Excess_Returns!$C$1:$V$1,0)), INDEX(Excess_Returns!$C$3:$V$62,0,MATCH(L$2,Excess_Returns!$C$1:$V$1,0)) ) -> 0.0014983474 | M16: =_xlfn.COVARIANCE.S( INDEX(Excess_Returns!$C$3:$V$62,0,MATCH($H16,Excess_Returns!$C$1:$V$1,0)), INDEX(Excess_Returns!$C$3:$V$62,0,MATCH(M$2,Excess_Returns!$C$1:$V$1,0)) ) -> 0.00045123111 | N16: =_xlfn.COVARIANCE.S( INDEX(Excess_Returns!$C$3:$V$62,0,MATCH($H16,Excess_Returns!$C$1:$V$1,0)), INDEX(Excess_Returns!$C$3:$V$62,0,MATCH(N$2,Excess_Returns!$C$1:$V$1,0)) ) -> 0.002745703 | O16: =_xlfn.COVARIANCE.S( INDEX(Excess_Returns!$C$3:$V$62,0,MATCH($H16,Excess_Returns!$C$1:$V$1,0)), INDEX(Excess_Returns!$C$3:$V$62,0,MATCH(O$2,Excess_Returns!$C$1:$V$1,0)) ) -> 0.0018438306 | P16: =_xlfn.COVARIANCE.S( INDEX(Excess_Returns!$C$3:$V$62,0,MATCH($H16,Excess_Returns!$C$1:$V$1,0)), INDEX(Excess_Returns!$C$3:$V$62,0,MATCH(P$2,Excess_Returns!$C$1:$V$1,0)) ) -> 0.0029694773 | ... AB16: =_xlfn.COVARIANCE.S( INDEX(Excess_Returns!$C$3:$V$62,0,MATCH($H16,Excess_Returns!$C$1:$V$1,0)), INDEX(Excess_Returns!$C$3:$V$62,0,MATCH(AB$2,Excess_Returns!$C$1:$V$1,0)) ) -> 0.0032238831
A17: OXY.US | B17: =AVERAGE(Excess_Returns!Q$2:Q$62) -> 0.022271314 | C17: =_xlfn.STDEV.S(Excess_Returns!Q2:Q62) -> 0.19140576 | E17: =SLOPE(Excess_Returns!$C$3:$C$62,Excess_Returns!$B$3:$B$62) -> 1.2365339 | H17: {=INDEX($A$3:$A$22, ROWS($H$3:H17))} -> OXY.US | I17: =_xlfn.COVARIANCE.S( INDEX(Excess_Returns!$C$3:$V$62,0,MATCH($H17,Excess_Returns!$C$1:$V$1,0)), INDEX(Excess_Returns!$C$3:$V$62,0,MATCH(I$2,Excess_Returns!$C$1:$V$1,0)) ) -> 0.0036315055 | J17: =_xlfn.COVARIANCE.S( INDEX(Excess_Returns!$C$3:$V$62,0,MATCH($H17,Excess_Returns!$C$1:$V$1,0)), INDEX(Excess_Returns!$C$3:$V$62,0,MATCH(J$2,Excess_Returns!$C$1:$V$1,0)) ) -> 0.002893169 | K17: =_xlfn.COVARIANCE.S( INDEX(Excess_Returns!$C$3:$V$62,0,MATCH($H17,Excess_Returns!$C$1:$V$1,0)), INDEX(Excess_Returns!$C$3:$V$62,0,MATCH(K$2,Excess_Returns!$C$1:$V$1,0)) ) -> 0.0042691048 | L17: =_xlfn.COVARIANCE.S( INDEX(Excess_Returns!$C$3:$V$62,0,MATCH($H17,Excess_Returns!$C$1:$V$1,0)), INDEX(Excess_Returns!$C$3:$V$62,0,MATCH(L$2,Excess_Returns!$C$1:$V$1,0)) ) -> 0.00070182775 | M17: =_xlfn.COVARIANCE.S( INDEX(Excess_Returns!$C$3:$V$62,0,MATCH($H17,Excess_Returns!$C$1:$V$1,0)), INDEX(Excess_Returns!$C$3:$V$62,0,MATCH(M$2,Excess_Returns!$C$1:$V$1,0)) ) -> 0.00051478268 | N17: =_xlfn.COVARIANCE.S( INDEX(Excess_Returns!$C$3:$V$62,0,MATCH($H17,Excess_Returns!$C$1:$V$1,0)), INDEX(Excess_Returns!$C$3:$V$62,0,MATCH(N$2,Excess_Returns!$C$1:$V$1,0)) ) -> 0.0022162986 | O17: =_xlfn.COVARIANCE.S( INDEX(Excess_Returns!$C$3:$V$62,0,MATCH($H17,Excess_Returns!$C$1:$V$1,0)), INDEX(Excess_Returns!$C$3:$V$62,0,MATCH(O$2,Excess_Returns!$C$1:$V$1,0)) ) -> 0.00072178951 | P17: =_xlfn.COVARIANCE.S( INDEX(Excess_Returns!$C$3:$V$62,0,MATCH($H17,Excess_Returns!$C$1:$V$1,0)), INDEX(Excess_Returns!$C$3:$V$62,0,MATCH(P$2,Excess_Returns!$C$1:$V$1,0)) ) -> 0.0025534765 | ... AB17: =_xlfn.COVARIANCE.S( INDEX(Excess_Returns!$C$3:$V$62,0,MATCH($H17,Excess_Returns!$C$1:$V$1,0)), INDEX(Excess_Returns!$C$3:$V$62,0,MATCH(AB$2,Excess_Returns!$C$1:$V$1,0)) ) -> 0.0026463315
A18: AMZN.US | B18: =AVERAGE(Excess_Returns!R$2:R$62) -> 0.016300848 | C18: =_xlfn.STDEV.S(Excess_Returns!R2:R62) -> 0.094628763 | E18: =SLOPE(Excess_Returns!$C$3:$C$62,Excess_Returns!$B$3:$B$62) -> 1.2365339 | H18: {=INDEX($A$3:$A$22, ROWS($H$3:H18))} -> AMZN.US | I18: =_xlfn.COVARIANCE.S( INDEX(Excess_Returns!$C$3:$V$62,0,MATCH($H18,Excess_Returns!$C$1:$V$1,0)), INDEX(Excess_Returns!$C$3:$V$62,0,MATCH(I$2,Excess_Returns!$C$1:$V$1,0)) ) -> 0.0054614165 | J18: =_xlfn.COVARIANCE.S( INDEX(Excess_Returns!$C$3:$V$62,0,MATCH($H18,Excess_Returns!$C$1:$V$1,0)), INDEX(Excess_Returns!$C$3:$V$62,0,MATCH(J$2,Excess_Returns!$C$1:$V$1,0)) ) -> 0.0041274552 | K18: =_xlfn.COVARIANCE.S( INDEX(Excess_Returns!$C$3:$V$62,0,MATCH($H18,Excess_Returns!$C$1:$V$1,0)), INDEX(Excess_Returns!$C$3:$V$62,0,MATCH(K$2,Excess_Returns!$C$1:$V$1,0)) ) -> 0.0044610733 | L18: =_xlfn.COVARIANCE.S( INDEX(Excess_Returns!$C$3:$V$62,0,MATCH($H18,Excess_Returns!$C$1:$V$1,0)), INDEX(Excess_Returns!$C$3:$V$62,0,MATCH(L$2,Excess_Returns!$C$1:$V$1,0)) ) -> 0.0083513362 | M18: =_xlfn.COVARIANCE.S( INDEX(Excess_Returns!$C$3:$V$62,0,MATCH($H18,Excess_Returns!$C$1:$V$1,0)), INDEX(Excess_Returns!$C$3:$V$62,0,MATCH(M$2,Excess_Returns!$C$1:$V$1,0)) ) -> 0.0052265573 | N18: =_xlfn.COVARIANCE.S( INDEX(Excess_Returns!$C$3:$V$62,0,MATCH($H18,Excess_Returns!$C$1:$V$1,0)), INDEX(Excess_Returns!$C$3:$V$62,0,MATCH(N$2,Excess_Returns!$C$1:$V$1,0)) ) -> 0.00042907058 | O18: =_xlfn.COVARIANCE.S( INDEX(Excess_Returns!$C$3:$V$62,0,MATCH($H18,Excess_Returns!$C$1:$V$1,0)), INDEX(Excess_Returns!$C$3:$V$62,0,MATCH(O$2,Excess_Returns!$C$1:$V$1,0)) ) -> 0.00094751025 | P18: =_xlfn.COVARIANCE.S( INDEX(Excess_Returns!$C$3:$V$62,0,MATCH($H18,Excess_Returns!$C$1:$V$1,0)), INDEX(Excess_Returns!$C$3:$V$62,0,MATCH(P$2,Excess_Returns!$C$1:$V$1,0)) ) -> 0.00093911504 | ... AB18: =_xlfn.COVARIANCE.S( INDEX(Excess_Returns!$C$3:$V$62,0,MATCH($H18,Excess_Returns!$C$1:$V$1,0)), INDEX(Excess_Returns!$C$3:$V$62,0,MATCH(AB$2,Excess_Returns!$C$1:$V$1,0)) ) -> 0.001390485
A19: TSLA.US | B19: =AVERAGE(Excess_Returns!S$2:S$62) -> 0.066524749 | C19: =_xlfn.STDEV.S(Excess_Returns!S2:S62) -> 0.22299138 | E19: =SLOPE(Excess_Returns!$C$3:$C$62,Excess_Returns!$B$3:$B$62) -> 1.2365339 | H19: {=INDEX($A$3:$A$22, ROWS($H$3:H19))} -> TSLA.US | I19: =_xlfn.COVARIANCE.S( INDEX(Excess_Returns!$C$3:$V$62,0,MATCH($H19,Excess_Returns!$C$1:$V$1,0)), INDEX(Excess_Returns!$C$3:$V$62,0,MATCH(I$2,Excess_Returns!$C$1:$V$1,0)) ) -> 0.013124232 | J19: =_xlfn.COVARIANCE.S( INDEX(Excess_Returns!$C$3:$V$62,0,MATCH($H19,Excess_Returns!$C$1:$V$1,0)), INDEX(Excess_Returns!$C$3:$V$62,0,MATCH(J$2,Excess_Returns!$C$1:$V$1,0)) ) -> 0.0075667094 | K19: =_xlfn.COVARIANCE.S( INDEX(Excess_Returns!$C$3:$V$62,0,MATCH($H19,Excess_Returns!$C$1:$V$1,0)), INDEX(Excess_Returns!$C$3:$V$62,0,MATCH(K$2,Excess_Returns!$C$1:$V$1,0)) ) -> 0.0075805037 | L19: =_xlfn.COVARIANCE.S( INDEX(Excess_Returns!$C$3:$V$62,0,MATCH($H19,Excess_Returns!$C$1:$V$1,0)), INDEX(Excess_Returns!$C$3:$V$62,0,MATCH(L$2,Excess_Returns!$C$1:$V$1,0)) ) -> 0.012839548 | M19: =_xlfn.COVARIANCE.S( INDEX(Excess_Returns!$C$3:$V$62,0,MATCH($H19,Excess_Returns!$C$1:$V$1,0)), INDEX(Excess_Returns!$C$3:$V$62,0,MATCH(M$2,Excess_Returns!$C$1:$V$1,0)) ) -> 0.0080874683 | N19: =_xlfn.COVARIANCE.S( INDEX(Excess_Returns!$C$3:$V$62,0,MATCH($H19,Excess_Returns!$C$1:$V$1,0)), INDEX(Excess_Returns!$C$3:$V$62,0,MATCH(N$2,Excess_Returns!$C$1:$V$1,0)) ) -> 0.0025306202 | O19: =_xlfn.COVARIANCE.S( INDEX(Excess_Returns!$C$3:$V$62,0,MATCH($H19,Excess_Returns!$C$1:$V$1,0)), INDEX(Excess_Returns!$C$3:$V$62,0,MATCH(O$2,Excess_Returns!$C$1:$V$1,0)) ) -> 0.0015945273 | P19: =_xlfn.COVARIANCE.S( INDEX(Excess_Returns!$C$3:$V$62,0,MATCH($H19,Excess_Returns!$C$1:$V$1,0)), INDEX(Excess_Returns!$C$3:$V$62,0,MATCH(P$2,Excess_Returns!$C$1:$V$1,0)) ) -> 0.0032709083 | ... AB19: =_xlfn.COVARIANCE.S( INDEX(Excess_Returns!$C$3:$V$62,0,MATCH($H19,Excess_Returns!$C$1:$V$1,0)), INDEX(Excess_Returns!$C$3:$V$62,0,MATCH(AB$2,Excess_Returns!$C$1:$V$1,0)) ) -> 0.0045630376
A20: NKE.US | B20: =AVERAGE(Excess_Returns!T$2:T$62) -> -0.00036677157 | C20: =_xlfn.STDEV.S(Excess_Returns!T2:T62) -> 0.090408619 | E20: =SLOPE(Excess_Returns!$C$3:$C$62,Excess_Returns!$B$3:$B$62) -> 1.2365339 | H20: {=INDEX($A$3:$A$22, ROWS($H$3:H20))} -> NKE.US | I20: =_xlfn.COVARIANCE.S( INDEX(Excess_Returns!$C$3:$V$62,0,MATCH($H20,Excess_Returns!$C$1:$V$1,0)), INDEX(Excess_Returns!$C$3:$V$62,0,MATCH(I$2,Excess_Returns!$C$1:$V$1,0)) ) -> 0.0035836588 | J20: =_xlfn.COVARIANCE.S( INDEX(Excess_Returns!$C$3:$V$62,0,MATCH($H20,Excess_Returns!$C$1:$V$1,0)), INDEX(Excess_Returns!$C$3:$V$62,0,MATCH(J$2,Excess_Returns!$C$1:$V$1,0)) ) -> 0.002886049 | K20: =_xlfn.COVARIANCE.S( INDEX(Excess_Returns!$C$3:$V$62,0,MATCH($H20,Excess_Returns!$C$1:$V$1,0)), INDEX(Excess_Returns!$C$3:$V$62,0,MATCH(K$2,Excess_Returns!$C$1:$V$1,0)) ) -> 0.0018362672 | L20: =_xlfn.COVARIANCE.S( INDEX(Excess_Returns!$C$3:$V$62,0,MATCH($H20,Excess_Returns!$C$1:$V$1,0)), INDEX(Excess_Returns!$C$3:$V$62,0,MATCH(L$2,Excess_Returns!$C$1:$V$1,0)) ) -> 0.0046617293 | M20: =_xlfn.COVARIANCE.S( INDEX(Excess_Returns!$C$3:$V$62,0,MATCH($H20,Excess_Returns!$C$1:$V$1,0)), INDEX(Excess_Returns!$C$3:$V$62,0,MATCH(M$2,Excess_Returns!$C$1:$V$1,0)) ) -> 0.0034294219 | N20: =_xlfn.COVARIANCE.S( INDEX(Excess_Returns!$C$3:$V$62,0,MATCH($H20,Excess_Returns!$C$1:$V$1,0)), INDEX(Excess_Returns!$C$3:$V$62,0,MATCH(N$2,Excess_Returns!$C$1:$V$1,0)) ) -> 0.0015338073 | O20: =_xlfn.COVARIANCE.S( INDEX(Excess_Returns!$C$3:$V$62,0,MATCH($H20,Excess_Returns!$C$1:$V$1,0)), INDEX(Excess_Returns!$C$3:$V$62,0,MATCH(O$2,Excess_Returns!$C$1:$V$1,0)) ) -> 0.0016547678 | P20: =_xlfn.COVARIANCE.S( INDEX(Excess_Returns!$C$3:$V$62,0,MATCH($H20,Excess_Returns!$C$1:$V$1,0)), INDEX(Excess_Returns!$C$3:$V$62,0,MATCH(P$2,Excess_Returns!$C$1:$V$1,0)) ) -> 0.0020038193 | ... AB20: =_xlfn.COVARIANCE.S( INDEX(Excess_Returns!$C$3:$V$62,0,MATCH($H20,Excess_Returns!$C$1:$V$1,0)), INDEX(Excess_Returns!$C$3:$V$62,0,MATCH(AB$2,Excess_Returns!$C$1:$V$1,0)) ) -> 0.002791527
A21: HD.US | B21: =AVERAGE(Excess_Returns!U$2:U$62) -> 0.013007073 | C21: =_xlfn.STDEV.S(Excess_Returns!U2:U62) -> 0.073387187 | E21: =SLOPE(Excess_Returns!$C$3:$C$62,Excess_Returns!$B$3:$B$62) -> 1.2365339 | H21: {=INDEX($A$3:$A$22, ROWS($H$3:H21))} -> HD.US | I21: =_xlfn.COVARIANCE.S( INDEX(Excess_Returns!$C$3:$V$62,0,MATCH($H21,Excess_Returns!$C$1:$V$1,0)), INDEX(Excess_Returns!$C$3:$V$62,0,MATCH(I$2,Excess_Returns!$C$1:$V$1,0)) ) -> 0.0031186886 | J21: =_xlfn.COVARIANCE.S( INDEX(Excess_Returns!$C$3:$V$62,0,MATCH($H21,Excess_Returns!$C$1:$V$1,0)), INDEX(Excess_Returns!$C$3:$V$62,0,MATCH(J$2,Excess_Returns!$C$1:$V$1,0)) ) -> 0.0023634699 | K21: =_xlfn.COVARIANCE.S( INDEX(Excess_Returns!$C$3:$V$62,0,MATCH($H21,Excess_Returns!$C$1:$V$1,0)), INDEX(Excess_Returns!$C$3:$V$62,0,MATCH(K$2,Excess_Returns!$C$1:$V$1,0)) ) -> 0.0020944728 | L21: =_xlfn.COVARIANCE.S( INDEX(Excess_Returns!$C$3:$V$62,0,MATCH($H21,Excess_Returns!$C$1:$V$1,0)), INDEX(Excess_Returns!$C$3:$V$62,0,MATCH(L$2,Excess_Returns!$C$1:$V$1,0)) ) -> 0.0038535434 | M21: =_xlfn.COVARIANCE.S( INDEX(Excess_Returns!$C$3:$V$62,0,MATCH($H21,Excess_Returns!$C$1:$V$1,0)), INDEX(Excess_Returns!$C$3:$V$62,0,MATCH(M$2,Excess_Returns!$C$1:$V$1,0)) ) -> 0.0040315628 | N21: =_xlfn.COVARIANCE.S( INDEX(Excess_Returns!$C$3:$V$62,0,MATCH($H21,Excess_Returns!$C$1:$V$1,0)), INDEX(Excess_Returns!$C$3:$V$62,0,MATCH(N$2,Excess_Returns!$C$1:$V$1,0)) ) -> 0.0016977379 | O21: =_xlfn.COVARIANCE.S( INDEX(Excess_Returns!$C$3:$V$62,0,MATCH($H21,Excess_Returns!$C$1:$V$1,0)), INDEX(Excess_Returns!$C$3:$V$62,0,MATCH(O$2,Excess_Returns!$C$1:$V$1,0)) ) -> 0.0026632855 | P21: =_xlfn.COVARIANCE.S( INDEX(Excess_Returns!$C$3:$V$62,0,MATCH($H21,Excess_Returns!$C$1:$V$1,0)), INDEX(Excess_Returns!$C$3:$V$62,0,MATCH(P$2,Excess_Returns!$C$1:$V$1,0)) ) -> 0.0019025989 | ... AB21: =_xlfn.COVARIANCE.S( INDEX(Excess_Returns!$C$3:$V$62,0,MATCH($H21,Excess_Returns!$C$1:$V$1,0)), INDEX(Excess_Returns!$C$3:$V$62,0,MATCH(AB$2,Excess_Returns!$C$1:$V$1,0)) ) -> 0.0027503045
A22: MCD.US | B22: =AVERAGE(Excess_Returns!V$2:V$62) -> 0.0076791872 | C22: =_xlfn.STDEV.S(Excess_Returns!V2:V62) -> 0.056323978 | E22: =SLOPE(Excess_Returns!$C$3:$C$62,Excess_Returns!$B$3:$B$62) -> 1.2365339 | H22: {=INDEX($A$3:$A$22, ROWS($H$3:H22))} -> MCD.US | I22: =_xlfn.COVARIANCE.S( INDEX(Excess_Returns!$C$3:$V$62,0,MATCH($H22,Excess_Returns!$C$1:$V$1,0)), INDEX(Excess_Returns!$C$3:$V$62,0,MATCH(I$2,Excess_Returns!$C$1:$V$1,0)) ) -> 0.002752348 | J22: =_xlfn.COVARIANCE.S( INDEX(Excess_Returns!$C$3:$V$62,0,MATCH($H22,Excess_Returns!$C$1:$V$1,0)), INDEX(Excess_Returns!$C$3:$V$62,0,MATCH(J$2,Excess_Returns!$C$1:$V$1,0)) ) -> 0.001488617 | K22: =_xlfn.COVARIANCE.S( INDEX(Excess_Returns!$C$3:$V$62,0,MATCH($H22,Excess_Returns!$C$1:$V$1,0)), INDEX(Excess_Returns!$C$3:$V$62,0,MATCH(K$2,Excess_Returns!$C$1:$V$1,0)) ) -> 0.0014496785 | L22: =_xlfn.COVARIANCE.S( INDEX(Excess_Returns!$C$3:$V$62,0,MATCH($H22,Excess_Returns!$C$1:$V$1,0)), INDEX(Excess_Returns!$C$3:$V$62,0,MATCH(L$2,Excess_Returns!$C$1:$V$1,0)) ) -> 0.0011945656 | M22: =_xlfn.COVARIANCE.S( INDEX(Excess_Returns!$C$3:$V$62,0,MATCH($H22,Excess_Returns!$C$1:$V$1,0)), INDEX(Excess_Returns!$C$3:$V$62,0,MATCH(M$2,Excess_Returns!$C$1:$V$1,0)) ) -> 0.0016348892 | N22: =_xlfn.COVARIANCE.S( INDEX(Excess_Returns!$C$3:$V$62,0,MATCH($H22,Excess_Returns!$C$1:$V$1,0)), INDEX(Excess_Returns!$C$3:$V$62,0,MATCH(N$2,Excess_Returns!$C$1:$V$1,0)) ) -> 0.0016543532 | O22: =_xlfn.COVARIANCE.S( INDEX(Excess_Returns!$C$3:$V$62,0,MATCH($H22,Excess_Returns!$C$1:$V$1,0)), INDEX(Excess_Returns!$C$3:$V$62,0,MATCH(O$2,Excess_Returns!$C$1:$V$1,0)) ) -> 0.0016676871 | P22: =_xlfn.COVARIANCE.S( INDEX(Excess_Returns!$C$3:$V$62,0,MATCH($H22,Excess_Returns!$C$1:$V$1,0)), INDEX(Excess_Returns!$C$3:$V$62,0,MATCH(P$2,Excess_Returns!$C$1:$V$1,0)) ) -> 0.0016076724 | ... AB22: =_xlfn.COVARIANCE.S( INDEX(Excess_Returns!$C$3:$V$62,0,MATCH($H22,Excess_Returns!$C$1:$V$1,0)), INDEX(Excess_Returns!$C$3:$V$62,0,MATCH(AB$2,Excess_Returns!$C$1:$V$1,0)) ) -> 0.0031723904

Sheet MV_HighBeta
